2025-04-25 09:25:50 - INFO - Airflow DAG has started.
2025-04-25 09:25:56 - WARNING - File ga_sessions_new_2022-01-01.json contains no valid sessions. Skipping.
2025-04-25 09:25:56 - INFO - File ga_sessions_new_2022-01-02.json has already been loaded. Skipping.
2025-04-25 09:26:07 - WARNING - File ga_hits_new_2022-01-01.json contains no valid sessions. Skipping.
2025-04-25 09:26:07 - WARNING - File ga_hits_new_2022-01-02.json has already been loaded. Skipping.
2025-04-25 09:26:07 - INFO - All files have been processed.
2025-04-26 17:47:08 - WARNING - PROJECT_PATH is not set. Using current directory as default.
2025-04-26 17:47:08 - INFO - Metrics pushed to Pushgateway
2025-04-26 17:50:32 - WARNING - PROJECT_PATH is not set. Using current directory as default.
2025-04-26 17:50:32 - WARNING - File ga_hits_new_2022-01-01.json contains no valid sessions. Skipping.
2025-04-26 17:50:32 - WARNING - File ga_hits_new_2022-01-02.json has already been loaded. Skipping.
2025-04-26 17:50:32 - INFO - All files have been processed.
2025-04-26 17:50:32 - INFO - Metrics pushed to Pushgateway
2025-04-26 17:56:48 - WARNING - PROJECT_PATH is not set. Using current directory as default.
2025-04-26 17:56:49 - INFO - Metrics pushed to Pushgateway
2025-05-02 19:41:02 - INFO - ETL process started
2025-05-02 19:41:19 - ERROR - Failed to send log to Elasticsearch: Connection error caused by: ConnectionError(Connection error caused by: NewConnectionError(<urllib3.connection.HTTPConnection object at 0x00000148F5F15C60>: Failed to establish a new connection: [Errno 11001] getaddrinfo failed))
2025-05-02 19:41:45 - ERROR - Failed to send log to Elasticsearch: Connection error caused by: ConnectionError(Connection error caused by: NewConnectionError(<urllib3.connection.HTTPConnection object at 0x00000148F5F16CB0>: Failed to establish a new connection: [Errno 11001] getaddrinfo failed))
2025-05-02 20:02:00 - INFO - Airflow DAG has started.
2025-05-02 20:02:16 - ERROR - Failed to send log to Elasticsearch: Connection error caused by: ConnectionError(Connection error caused by: NewConnectionError(<urllib3.connection.HTTPConnection object at 0x000002C0BF58F6A0>: Failed to establish a new connection: [Errno 11001] getaddrinfo failed))
2025-05-02 20:02:42 - ERROR - Failed to send log to Elasticsearch: Connection error caused by: ConnectionError(Connection error caused by: NewConnectionError(<urllib3.connection.HTTPConnection object at 0x000002C0BF58D3F0>: Failed to establish a new connection: [Errno 11001] getaddrinfo failed))
2025-05-02 20:03:09 - ERROR - Failed to send log to Elasticsearch: Connection error caused by: ConnectionError(Connection error caused by: NewConnectionError(<urllib3.connection.HTTPConnection object at 0x000002C0BF58EAD0>: Failed to establish a new connection: [Errno 11001] getaddrinfo failed))
2025-05-02 20:03:35 - ERROR - Failed to send log to Elasticsearch: Connection error caused by: ConnectionError(Connection error caused by: NewConnectionError(<urllib3.connection.HTTPConnection object at 0x000002C0BF68CF10>: Failed to establish a new connection: [Errno 11001] getaddrinfo failed))
2025-05-02 20:04:01 - ERROR - Failed to send log to Elasticsearch: Connection error caused by: ConnectionError(Connection error caused by: NewConnectionError(<urllib3.connection.HTTPConnection object at 0x000002C0BF68E200>: Failed to establish a new connection: [Errno 11001] getaddrinfo failed))
2025-05-02 20:04:01 - ERROR - Log could not be sent to Elasticsearch.
2025-05-02 20:04:01 - WARNING - Potential issue detected.
2025-05-02 20:04:17 - ERROR - Failed to send log to Elasticsearch: Connection error caused by: ConnectionError(Connection error caused by: NewConnectionError(<urllib3.connection.HTTPConnection object at 0x000002C0BF68F670>: Failed to establish a new connection: [Errno 11001] getaddrinfo failed))
2025-05-02 20:04:43 - ERROR - Failed to send log to Elasticsearch: Connection error caused by: ConnectionError(Connection error caused by: NewConnectionError(<urllib3.connection.HTTPConnection object at 0x000002C0BF6E07F0>: Failed to establish a new connection: [Errno 11001] getaddrinfo failed))
2025-05-02 20:05:10 - ERROR - Failed to send log to Elasticsearch: Connection error caused by: ConnectionError(Connection error caused by: NewConnectionError(<urllib3.connection.HTTPConnection object at 0x000002C0BF6E1E10>: Failed to establish a new connection: [Errno 11001] getaddrinfo failed))
2025-05-02 20:05:36 - ERROR - Failed to send log to Elasticsearch: Connection error caused by: ConnectionError(Connection error caused by: NewConnectionError(<urllib3.connection.HTTPConnection object at 0x000002C0BF6E3100>: Failed to establish a new connection: [Errno 11001] getaddrinfo failed))
2025-05-02 20:06:02 - ERROR - Failed to send log to Elasticsearch: Connection error caused by: ConnectionError(Connection error caused by: NewConnectionError(<urllib3.connection.HTTPConnection object at 0x000002C0BF734430>: Failed to establish a new connection: [Errno 11001] getaddrinfo failed))
2025-05-02 20:06:02 - ERROR - Log could not be sent to Elasticsearch.
2025-05-02 20:06:02 - ERROR - Error while processing hits.
2025-05-03 12:52:23 - INFO - DAG sber_dag has been successfully configured and is ready to run.
2025-05-03 12:52:31 - INFO - DAG sber_dag has been successfully configured and is ready to run.
2025-05-03 12:52:44 - INFO - DAG sber_dag has been successfully configured and is ready to run.
2025-05-03 12:54:22 - INFO - DAG sber_dag has been successfully configured and is ready to run.
2025-05-03 12:54:22 - INFO - DAG sber_dag has been successfully configured and is ready to run.
2025-05-03 12:54:22 - WARNING - File ga_sessions_new_2022-01-01.json contains no valid sessions. Skipping.
2025-05-03 12:54:38 - ERROR - Failed to send log to Elasticsearch: Connection error caused by: ConnectionError(Connection error caused by: NewConnectionError(<urllib3.connection.HTTPConnection object at 0x0000029CCBD5F7C0>: Failed to establish a new connection: [Errno 11001] getaddrinfo failed))
2025-05-03 12:55:04 - ERROR - Failed to send log to Elasticsearch: Connection error caused by: ConnectionError(Connection error caused by: NewConnectionError(<urllib3.connection.HTTPConnection object at 0x0000029CCBD5DC30>: Failed to establish a new connection: [Errno 11001] getaddrinfo failed))
2025-05-03 12:55:31 - ERROR - Failed to send log to Elasticsearch: Connection error caused by: ConnectionError(Connection error caused by: NewConnectionError(<urllib3.connection.HTTPConnection object at 0x0000029CCBE50250>: Failed to establish a new connection: [Errno 11001] getaddrinfo failed))
2025-05-03 12:55:57 - ERROR - Failed to send log to Elasticsearch: Connection error caused by: ConnectionError(Connection error caused by: NewConnectionError(<urllib3.connection.HTTPConnection object at 0x0000029CCBE514E0>: Failed to establish a new connection: [Errno 11001] getaddrinfo failed))
2025-05-03 12:56:23 - ERROR - Failed to send log to Elasticsearch: Connection error caused by: ConnectionError(Connection error caused by: NewConnectionError(<urllib3.connection.HTTPConnection object at 0x0000029CCBE527D0>: Failed to establish a new connection: [Errno 11001] getaddrinfo failed))
2025-05-03 12:56:23 - ERROR - Failed to send log to Elasticsearch: RetryError[<Future at 0x29ccbe524d0 state=finished raised ConnectionError>]
2025-05-03 12:56:23 - INFO - Transformed data saved to C:\Users\Ekaterina\sber_de\de_for_sber\data\processed\new_sessions\ga_sessions_new_2022-01-02.pkl
2025-05-03 12:56:23 - INFO - All files have been processed.
2025-05-06 13:52:12 - WARNING - File ga_sessions_new_2022-01-01.json contains no valid sessions. Skipping.
2025-05-06 13:52:29 - ERROR - Failed to send log to Elasticsearch: Connection error caused by: ConnectionError(Connection error caused by: NewConnectionError(<urllib3.connection.HTTPConnection object at 0x0000023A541F4430>: Failed to establish a new connection: [Errno 11001] getaddrinfo failed))
2025-05-06 13:52:55 - ERROR - Failed to send log to Elasticsearch: Connection error caused by: ConnectionError(Connection error caused by: NewConnectionError(<urllib3.connection.HTTPConnection object at 0x0000023A541F54B0>: Failed to establish a new connection: [Errno 11001] getaddrinfo failed))
2025-05-06 13:53:21 - ERROR - Failed to send log to Elasticsearch: Connection error caused by: ConnectionError(Connection error caused by: NewConnectionError(<urllib3.connection.HTTPConnection object at 0x0000023A541F6320>: Failed to establish a new connection: [Errno 11001] getaddrinfo failed))
2025-05-06 13:53:47 - ERROR - Failed to send log to Elasticsearch: Connection error caused by: ConnectionError(Connection error caused by: NewConnectionError(<urllib3.connection.HTTPConnection object at 0x0000023A541F61D0>: Failed to establish a new connection: [Errno 11001] getaddrinfo failed))
2025-05-06 13:54:13 - ERROR - Failed to send log to Elasticsearch: Connection error caused by: ConnectionError(Connection error caused by: NewConnectionError(<urllib3.connection.HTTPConnection object at 0x0000023A541F51B0>: Failed to establish a new connection: [Errno 11001] getaddrinfo failed))
2025-05-06 13:54:14 - ERROR - Failed to send log to Elasticsearch: RetryError[<Future at 0x23a541f64d0 state=finished raised ConnectionError>]
2025-05-06 13:54:14 - WARNING - File ga_sessions_new_2022-01-02.json has already been loaded. Skipping.
2025-05-06 13:54:30 - ERROR - Failed to send log to Elasticsearch: Connection error caused by: ConnectionError(Connection error caused by: NewConnectionError(<urllib3.connection.HTTPConnection object at 0x0000023A5424C160>: Failed to establish a new connection: [Errno 11001] getaddrinfo failed))
2025-05-06 13:54:56 - ERROR - Failed to send log to Elasticsearch: Connection error caused by: ConnectionError(Connection error caused by: NewConnectionError(<urllib3.connection.HTTPConnection object at 0x0000023A5424D240>: Failed to establish a new connection: [Errno 11001] getaddrinfo failed))
2025-05-06 13:55:23 - ERROR - Failed to send log to Elasticsearch: Connection error caused by: ConnectionError(Connection error caused by: NewConnectionError(<urllib3.connection.HTTPConnection object at 0x0000023A5424C550>: Failed to establish a new connection: [Errno 11001] getaddrinfo failed))
2025-05-06 13:55:49 - ERROR - Failed to send log to Elasticsearch: Connection error caused by: ConnectionError(Connection error caused by: NewConnectionError(<urllib3.connection.HTTPConnection object at 0x0000023A5424C5B0>: Failed to establish a new connection: [Errno 11001] getaddrinfo failed))
2025-05-06 13:56:15 - ERROR - Failed to send log to Elasticsearch: Connection error caused by: ConnectionError(Connection error caused by: NewConnectionError(<urllib3.connection.HTTPConnection object at 0x0000023A5424C520>: Failed to establish a new connection: [Errno 11001] getaddrinfo failed))
2025-05-06 13:56:15 - ERROR - Failed to send log to Elasticsearch: RetryError[<Future at 0x23a541f66b0 state=finished raised ConnectionError>]
2025-05-06 13:56:15 - INFO - All files have been processed.
2025-05-06 13:59:49 - WARNING - File ga_sessions_new_2022-01-01.json contains no valid sessions. Skipping.
2025-05-06 14:00:05 - ERROR - Failed to send log to Elasticsearch: Connection error caused by: ConnectionError(Connection error caused by: NewConnectionError(<urllib3.connection.HTTPConnection object at 0x000001D5FEB544C0>: Failed to establish a new connection: [Errno 11001] getaddrinfo failed))
2025-05-06 14:00:31 - ERROR - Failed to send log to Elasticsearch: Connection error caused by: ConnectionError(Connection error caused by: NewConnectionError(<urllib3.connection.HTTPConnection object at 0x000001D5FEB55540>: Failed to establish a new connection: [Errno 11001] getaddrinfo failed))
2025-05-06 14:00:57 - ERROR - Failed to send log to Elasticsearch: Connection error caused by: ConnectionError(Connection error caused by: NewConnectionError(<urllib3.connection.HTTPConnection object at 0x000001D5FEB563B0>: Failed to establish a new connection: [Errno 11001] getaddrinfo failed))
2025-05-06 14:01:24 - ERROR - Failed to send log to Elasticsearch: Connection error caused by: ConnectionError(Connection error caused by: NewConnectionError(<urllib3.connection.HTTPConnection object at 0x000001D5FEB57490>: Failed to establish a new connection: [Errno 11001] getaddrinfo failed))
2025-05-06 14:01:50 - ERROR - Failed to send log to Elasticsearch: Connection error caused by: ConnectionError(Connection error caused by: NewConnectionError(<urllib3.connection.HTTPConnection object at 0x000001D5FEB563E0>: Failed to establish a new connection: [Errno 11001] getaddrinfo failed))
2025-05-06 14:01:50 - ERROR - Failed to send log to Elasticsearch: RetryError[<Future at 0x1d5feb567a0 state=finished raised ConnectionError>]
2025-05-06 14:01:50 - INFO - Transformed data saved to C:\Users\Ekaterina\sber_de\de_for_sber\data\processed\new_sessions\ga_sessions_new_2022-01-02.pkl
2025-05-06 14:01:50 - INFO - All files have been processed.
2025-05-06 14:08:35 - WARNING - File ga_sessions_new_2022-01-01.json contains no valid sessions. Skipping.
2025-05-06 14:08:51 - ERROR - Failed to send log to Elasticsearch: Connection error caused by: ConnectionError(Connection error caused by: NewConnectionError(<urllib3.connection.HTTPConnection object at 0x0000020D9FECB5B0>: Failed to establish a new connection: [Errno 11001] getaddrinfo failed))
2025-05-06 14:09:17 - ERROR - Failed to send log to Elasticsearch: Connection error caused by: ConnectionError(Connection error caused by: NewConnectionError(<urllib3.connection.HTTPConnection object at 0x0000020D9FECA7D0>: Failed to establish a new connection: [Errno 11001] getaddrinfo failed))
2025-05-06 14:09:44 - ERROR - Failed to send log to Elasticsearch: Connection error caused by: ConnectionError(Connection error caused by: NewConnectionError(<urllib3.connection.HTTPConnection object at 0x0000020D9FEC9960>: Failed to establish a new connection: [Errno 11001] getaddrinfo failed))
2025-05-06 14:11:29 - ERROR - Failed to load flags: Error 11001 connecting to redis_flags:6379. getaddrinfo failed.
2025-05-06 14:11:46 - ERROR - Failed to send log to Elasticsearch: Connection error caused by: ConnectionError(Connection error caused by: NewConnectionError(<urllib3.connection.HTTPConnection object at 0x000001AB2376C610>: Failed to establish a new connection: [Errno 11001] getaddrinfo failed))
2025-05-06 14:12:27 - WARNING - File ga_sessions_new_2022-01-01.json contains no valid sessions. Skipping.
2025-05-06 14:12:43 - ERROR - Failed to send log to Elasticsearch: Connection error caused by: ConnectionError(Connection error caused by: NewConnectionError(<urllib3.connection.HTTPConnection object at 0x000001CCD38F42E0>: Failed to establish a new connection: [Errno 11001] getaddrinfo failed))
2025-05-06 14:13:09 - ERROR - Failed to send log to Elasticsearch: Connection error caused by: ConnectionError(Connection error caused by: NewConnectionError(<urllib3.connection.HTTPConnection object at 0x000001CCD38F5360>: Failed to establish a new connection: [Errno 11001] getaddrinfo failed))
2025-05-06 14:13:35 - ERROR - Failed to send log to Elasticsearch: Connection error caused by: ConnectionError(Connection error caused by: NewConnectionError(<urllib3.connection.HTTPConnection object at 0x000001CCD38F61D0>: Failed to establish a new connection: [Errno 11001] getaddrinfo failed))
2025-05-06 14:14:02 - ERROR - Failed to send log to Elasticsearch: Connection error caused by: ConnectionError(Connection error caused by: NewConnectionError(<urllib3.connection.HTTPConnection object at 0x000001CCD38F7040>: Failed to establish a new connection: [Errno 11001] getaddrinfo failed))
2025-05-06 14:14:28 - ERROR - Failed to send log to Elasticsearch: Connection error caused by: ConnectionError(Connection error caused by: NewConnectionError(<urllib3.connection.HTTPConnection object at 0x000001CCD3954160>: Failed to establish a new connection: [Errno 11001] getaddrinfo failed))
2025-05-06 14:14:28 - ERROR - Failed to send log to Elasticsearch: RetryError[<Future at 0x1ccd38dff70 state=finished raised ConnectionError>]
2025-05-06 14:14:28 - INFO - Transformed data saved to C:\Users\Ekaterina\sber_de\de_for_sber\data\processed\new_sessions\ga_sessions_new_2022-01-02.pkl
2025-05-06 14:14:28 - INFO - All files have been processed.
2025-05-06 14:16:11 - INFO - Flags file not found, creating new one
2025-05-06 14:16:11 - WARNING - File ga_sessions_new_2022-01-01.json contains no valid sessions. Skipping.
2025-05-06 14:16:28 - ERROR - Failed to send log to Elasticsearch: Connection error caused by: ConnectionError(Connection error caused by: NewConnectionError(<urllib3.connection.HTTPConnection object at 0x000001F1F2F04700>: Failed to establish a new connection: [Errno 11001] getaddrinfo failed))
2025-05-06 14:16:54 - ERROR - Failed to send log to Elasticsearch: Connection error caused by: ConnectionError(Connection error caused by: NewConnectionError(<urllib3.connection.HTTPConnection object at 0x000001F1F2F05330>: Failed to establish a new connection: [Errno 11001] getaddrinfo failed))
2025-05-06 14:17:20 - ERROR - Failed to send log to Elasticsearch: Connection error caused by: ConnectionError(Connection error caused by: NewConnectionError(<urllib3.connection.HTTPConnection object at 0x000001F1F2F061A0>: Failed to establish a new connection: [Errno 11001] getaddrinfo failed))
2025-05-06 14:17:46 - ERROR - Failed to send log to Elasticsearch: Connection error caused by: ConnectionError(Connection error caused by: NewConnectionError(<urllib3.connection.HTTPConnection object at 0x000001F1F2F07010>: Failed to establish a new connection: [Errno 11001] getaddrinfo failed))
2025-05-06 14:18:12 - ERROR - Failed to send log to Elasticsearch: Connection error caused by: ConnectionError(Connection error caused by: NewConnectionError(<urllib3.connection.HTTPConnection object at 0x000001F1F2F64130>: Failed to establish a new connection: [Errno 11001] getaddrinfo failed))
2025-05-06 14:18:12 - ERROR - Failed to send log to Elasticsearch: RetryError[<Future at 0x1f1f2f07e50 state=finished raised ConnectionError>]
2025-05-06 14:18:13 - INFO - Transformed data saved to C:\Users\Ekaterina\sber_de\de_for_sber\data\processed\new_sessions\ga_sessions_new_2022-01-02.pkl
2025-05-06 14:18:13 - INFO - All files have been processed.
2025-05-06 14:24:28 - WARNING - File ga_sessions_new_2022-01-01.json contains no valid sessions. Skipping.
2025-05-06 14:24:44 - ERROR - Failed to send log to Elasticsearch: Connection error caused by: ConnectionError(Connection error caused by: NewConnectionError(<urllib3.connection.HTTPConnection object at 0x00000135E8C4B700>: Failed to establish a new connection: [Errno 11001] getaddrinfo failed))
2025-05-06 14:25:11 - ERROR - Failed to send log to Elasticsearch: Connection error caused by: ConnectionError(Connection error caused by: NewConnectionError(<urllib3.connection.HTTPConnection object at 0x00000135E8C4A920>: Failed to establish a new connection: [Errno 11001] getaddrinfo failed))
2025-05-06 14:25:37 - ERROR - Failed to send log to Elasticsearch: Connection error caused by: ConnectionError(Connection error caused by: NewConnectionError(<urllib3.connection.HTTPConnection object at 0x00000135E8C49AB0>: Failed to establish a new connection: [Errno 11001] getaddrinfo failed))
2025-05-06 14:26:03 - ERROR - Failed to send log to Elasticsearch: Connection error caused by: ConnectionError(Connection error caused by: NewConnectionError(<urllib3.connection.HTTPConnection object at 0x00000135E8C49C00>: Failed to establish a new connection: [Errno 11001] getaddrinfo failed))
2025-05-06 14:26:29 - ERROR - Failed to send log to Elasticsearch: Connection error caused by: ConnectionError(Connection error caused by: NewConnectionError(<urllib3.connection.HTTPConnection object at 0x00000135E8C49EA0>: Failed to establish a new connection: [Errno 11001] getaddrinfo failed))
2025-05-06 14:26:29 - ERROR - Failed to send log to Elasticsearch: RetryError[<Future at 0x135e8c49900 state=finished raised ConnectionError>]
2025-05-06 14:26:29 - WARNING - File ga_sessions_new_2022-01-02.json has already been loaded. Skipping.
2025-05-06 14:26:46 - ERROR - Failed to send log to Elasticsearch: Connection error caused by: ConnectionError(Connection error caused by: NewConnectionError(<urllib3.connection.HTTPConnection object at 0x00000135E8C3FA90>: Failed to establish a new connection: [Errno 11001] getaddrinfo failed))
2025-05-06 14:27:12 - ERROR - Failed to send log to Elasticsearch: Connection error caused by: ConnectionError(Connection error caused by: NewConnectionError(<urllib3.connection.HTTPConnection object at 0x00000135E8C3E500>: Failed to establish a new connection: [Errno 11001] getaddrinfo failed))
2025-05-06 14:27:38 - ERROR - Failed to send log to Elasticsearch: Connection error caused by: ConnectionError(Connection error caused by: NewConnectionError(<urllib3.connection.HTTPConnection object at 0x00000135E8C3FC70>: Failed to establish a new connection: [Errno 11001] getaddrinfo failed))
2025-05-06 14:28:04 - ERROR - Failed to send log to Elasticsearch: Connection error caused by: ConnectionError(Connection error caused by: NewConnectionError(<urllib3.connection.HTTPConnection object at 0x00000135E8C3FBE0>: Failed to establish a new connection: [Errno 11001] getaddrinfo failed))
2025-05-06 14:28:31 - ERROR - Failed to send log to Elasticsearch: Connection error caused by: ConnectionError(Connection error caused by: NewConnectionError(<urllib3.connection.HTTPConnection object at 0x00000135E8C3FF70>: Failed to establish a new connection: [Errno 11001] getaddrinfo failed))
2025-05-06 14:28:31 - ERROR - Failed to send log to Elasticsearch: RetryError[<Future at 0x135e8c49ba0 state=finished raised ConnectionError>]
2025-05-06 14:28:31 - INFO - All files have been processed.
2025-05-06 14:43:28 - WARNING - File ga_sessions_new_2022-01-01.json contains no valid sessions. Skipping.
2025-05-06 14:43:44 - ERROR - Failed to send log to Elasticsearch: Connection error caused by: ConnectionError(Connection error caused by: NewConnectionError(<urllib3.connection.HTTPConnection object at 0x00000240778FB670>: Failed to establish a new connection: [Errno 11001] getaddrinfo failed))
2025-05-06 14:44:10 - ERROR - Failed to send log to Elasticsearch: Connection error caused by: ConnectionError(Connection error caused by: NewConnectionError(<urllib3.connection.HTTPConnection object at 0x00000240778FA890>: Failed to establish a new connection: [Errno 11001] getaddrinfo failed))
2025-05-06 14:44:37 - ERROR - Failed to send log to Elasticsearch: Connection error caused by: ConnectionError(Connection error caused by: NewConnectionError(<urllib3.connection.HTTPConnection object at 0x00000240778F9A20>: Failed to establish a new connection: [Errno 11001] getaddrinfo failed))
2025-05-06 14:45:03 - ERROR - Failed to send log to Elasticsearch: Connection error caused by: ConnectionError(Connection error caused by: NewConnectionError(<urllib3.connection.HTTPConnection object at 0x00000240778F9B70>: Failed to establish a new connection: [Errno 11001] getaddrinfo failed))
2025-05-06 14:45:33 - ERROR - Failed to send log to Elasticsearch: Connection error caused by: ConnectionError(Connection error caused by: NewConnectionError(<urllib3.connection.HTTPConnection object at 0x00000240778F9E10>: Failed to establish a new connection: [Errno 11001] getaddrinfo failed))
2025-05-06 14:45:33 - ERROR - Failed to send log to Elasticsearch: RetryError[<Future at 0x240778f9870 state=finished raised ConnectionError>]
2025-05-06 14:45:33 - WARNING - File ga_sessions_new_2022-01-02.json has already been loaded. Skipping.
2025-05-06 14:45:49 - ERROR - Failed to send log to Elasticsearch: Connection error caused by: ConnectionError(Connection error caused by: NewConnectionError(<urllib3.connection.HTTPConnection object at 0x00000240778D7A00>: Failed to establish a new connection: [Errno 11001] getaddrinfo failed))
2025-05-06 14:46:15 - ERROR - Failed to send log to Elasticsearch: Connection error caused by: ConnectionError(Connection error caused by: NewConnectionError(<urllib3.connection.HTTPConnection object at 0x00000240778D6500>: Failed to establish a new connection: [Errno 11001] getaddrinfo failed))
2025-05-07 22:13:51 - WARNING - File ga_sessions_new_2022-01-01.json contains no valid sessions. Skipping.
2025-05-07 22:14:07 - ERROR - Failed to send log to Elasticsearch: Connection error caused by: ConnectionError(Connection error caused by: NewConnectionError(<urllib3.connection.HTTPConnection object at 0x0000022E2C503790>: Failed to establish a new connection: [Errno 11001] getaddrinfo failed))
2025-05-07 22:14:34 - ERROR - Failed to send log to Elasticsearch: Connection error caused by: ConnectionError(Connection error caused by: NewConnectionError(<urllib3.connection.HTTPConnection object at 0x0000022E2C5022C0>: Failed to establish a new connection: [Errno 11001] getaddrinfo failed))
2025-05-07 22:15:00 - ERROR - Failed to send log to Elasticsearch: Connection error caused by: ConnectionError(Connection error caused by: NewConnectionError(<urllib3.connection.HTTPConnection object at 0x0000022E2C501450>: Failed to establish a new connection: [Errno 11001] getaddrinfo failed))
2025-05-07 22:15:26 - ERROR - Failed to send log to Elasticsearch: Connection error caused by: ConnectionError(Connection error caused by: NewConnectionError(<urllib3.connection.HTTPConnection object at 0x0000022E2C5015A0>: Failed to establish a new connection: [Errno 11001] getaddrinfo failed))
2025-05-07 22:15:52 - ERROR - Failed to send log to Elasticsearch: Connection error caused by: ConnectionError(Connection error caused by: NewConnectionError(<urllib3.connection.HTTPConnection object at 0x0000022E2C501840>: Failed to establish a new connection: [Errno 11001] getaddrinfo failed))
2025-05-07 22:15:52 - ERROR - Failed to send log to Elasticsearch: RetryError[<Future at 0x22e2c5012a0 state=finished raised ConnectionError>]
2025-05-07 22:15:52 - WARNING - File ga_sessions_new_2022-01-02.json has already been loaded. Skipping.
2025-05-07 22:16:09 - ERROR - Failed to send log to Elasticsearch: Connection error caused by: ConnectionError(Connection error caused by: NewConnectionError(<urllib3.connection.HTTPConnection object at 0x0000022E2C4CFF10>: Failed to establish a new connection: [Errno 11001] getaddrinfo failed))
2025-05-07 22:16:35 - ERROR - Failed to send log to Elasticsearch: Connection error caused by: ConnectionError(Connection error caused by: NewConnectionError(<urllib3.connection.HTTPConnection object at 0x0000022E2C4CE710>: Failed to establish a new connection: [Errno 11001] getaddrinfo failed))
2025-05-07 22:17:02 - ERROR - Failed to send log to Elasticsearch: Connection error caused by: ConnectionError(Connection error caused by: NewConnectionError(<urllib3.connection.HTTPConnection object at 0x0000022E2C4CF9D0>: Failed to establish a new connection: [Errno 11001] getaddrinfo failed))
2025-05-07 22:17:28 - ERROR - Failed to send log to Elasticsearch: Connection error caused by: ConnectionError(Connection error caused by: NewConnectionError(<urllib3.connection.HTTPConnection object at 0x0000022E2C4CF970>: Failed to establish a new connection: [Errno 11001] getaddrinfo failed))
2025-05-07 22:17:55 - ERROR - Failed to send log to Elasticsearch: Connection error caused by: ConnectionError(Connection error caused by: NewConnectionError(<urllib3.connection.HTTPConnection object at 0x0000022E2C5582B0>: Failed to establish a new connection: [Errno 11001] getaddrinfo failed))
2025-05-07 22:17:55 - ERROR - Failed to send log to Elasticsearch: RetryError[<Future at 0x22e2c4cf790 state=finished raised ConnectionError>]
2025-05-07 22:17:55 - INFO - All files have been processed.
2025-05-07 22:17:55 - INFO - Sending ga_sessions_new_2022-01-02.pkl to DB...
2025-05-07 22:17:55 - ERROR - DB load error for ga_sessions_new_2022-01-02.pkl: DLL load failed while importing _multiarray_umath: The specified module could not be found.
2025-05-07 22:18:11 - ERROR - Failed to send log to Elasticsearch: Connection error caused by: ConnectionError(Connection error caused by: NewConnectionError(<urllib3.connection.HTTPConnection object at 0x0000022E2C5F08E0>: Failed to establish a new connection: [Errno 11001] getaddrinfo failed))
2025-05-07 22:18:37 - ERROR - Failed to send log to Elasticsearch: Connection error caused by: ConnectionError(Connection error caused by: NewConnectionError(<urllib3.connection.HTTPConnection object at 0x0000022E2C5F1A80>: Failed to establish a new connection: [Errno 11001] getaddrinfo failed))
2025-05-07 22:19:03 - ERROR - Failed to send log to Elasticsearch: Connection error caused by: ConnectionError(Connection error caused by: NewConnectionError(<urllib3.connection.HTTPConnection object at 0x0000022E2C5F0E80>: Failed to establish a new connection: [Errno 11001] getaddrinfo failed))
2025-05-07 22:19:30 - ERROR - Failed to send log to Elasticsearch: Connection error caused by: ConnectionError(Connection error caused by: NewConnectionError(<urllib3.connection.HTTPConnection object at 0x0000022E2C5F2B60>: Failed to establish a new connection: [Errno 11001] getaddrinfo failed))
2025-05-07 22:19:56 - ERROR - Failed to send log to Elasticsearch: Connection error caused by: ConnectionError(Connection error caused by: NewConnectionError(<urllib3.connection.HTTPConnection object at 0x0000022E2C5F0D90>: Failed to establish a new connection: [Errno 11001] getaddrinfo failed))
2025-05-07 22:19:56 - ERROR - Failed to send log to Elasticsearch: RetryError[<Future at 0x22e2c5c5570 state=finished raised ConnectionError>]
2025-05-07 22:22:15 - WARNING - File ga_sessions_new_2022-01-01.json contains no valid sessions. Skipping.
2025-05-07 22:22:32 - ERROR - Failed to send log to Elasticsearch: Connection error caused by: ConnectionError(Connection error caused by: NewConnectionError(<urllib3.connection.HTTPConnection object at 0x000001C9398F8430>: Failed to establish a new connection: [Errno 11001] getaddrinfo failed))
2025-05-07 22:22:58 - ERROR - Failed to send log to Elasticsearch: Connection error caused by: ConnectionError(Connection error caused by: NewConnectionError(<urllib3.connection.HTTPConnection object at 0x000001C9398F94B0>: Failed to establish a new connection: [Errno 11001] getaddrinfo failed))
2025-05-07 22:23:24 - ERROR - Failed to send log to Elasticsearch: Connection error caused by: ConnectionError(Connection error caused by: NewConnectionError(<urllib3.connection.HTTPConnection object at 0x000001C9398FA050>: Failed to establish a new connection: [Errno 11001] getaddrinfo failed))
2025-05-07 22:23:50 - ERROR - Failed to send log to Elasticsearch: Connection error caused by: ConnectionError(Connection error caused by: NewConnectionError(<urllib3.connection.HTTPConnection object at 0x000001C9398F9090>: Failed to establish a new connection: [Errno 11001] getaddrinfo failed))
2025-05-07 22:24:17 - ERROR - Failed to send log to Elasticsearch: Connection error caused by: ConnectionError(Connection error caused by: NewConnectionError(<urllib3.connection.HTTPConnection object at 0x000001C9398F9750>: Failed to establish a new connection: [Errno 11001] getaddrinfo failed))
2025-05-07 22:24:17 - ERROR - Failed to send log to Elasticsearch: RetryError[<Future at 0x1c9398fb0d0 state=finished raised ConnectionError>]
2025-05-07 22:24:17 - WARNING - File ga_sessions_new_2022-01-02.json has already been loaded. Skipping.
2025-05-07 22:24:33 - ERROR - Failed to send log to Elasticsearch: Connection error caused by: ConnectionError(Connection error caused by: NewConnectionError(<urllib3.connection.HTTPConnection object at 0x000001C9398FB520>: Failed to establish a new connection: [Errno 11001] getaddrinfo failed))
2025-05-07 22:24:59 - ERROR - Failed to send log to Elasticsearch: Connection error caused by: ConnectionError(Connection error caused by: NewConnectionError(<urllib3.connection.HTTPConnection object at 0x000001C939944370>: Failed to establish a new connection: [Errno 11001] getaddrinfo failed))
2025-05-07 22:25:25 - ERROR - Failed to send log to Elasticsearch: Connection error caused by: ConnectionError(Connection error caused by: NewConnectionError(<urllib3.connection.HTTPConnection object at 0x000001C9398FBF70>: Failed to establish a new connection: [Errno 11001] getaddrinfo failed))
2025-05-07 22:25:51 - ERROR - Failed to send log to Elasticsearch: Connection error caused by: ConnectionError(Connection error caused by: NewConnectionError(<urllib3.connection.HTTPConnection object at 0x000001C939944430>: Failed to establish a new connection: [Errno 11001] getaddrinfo failed))
2025-05-07 22:26:18 - ERROR - Failed to send log to Elasticsearch: Connection error caused by: ConnectionError(Connection error caused by: NewConnectionError(<urllib3.connection.HTTPConnection object at 0x000001C939945270>: Failed to establish a new connection: [Errno 11001] getaddrinfo failed))
2025-05-07 22:26:18 - ERROR - Failed to send log to Elasticsearch: RetryError[<Future at 0x1c9398fbfd0 state=finished raised ConnectionError>]
2025-05-07 22:26:18 - INFO - All files have been processed.
2025-05-07 22:26:18 - INFO - Sending ga_sessions_new_2022-01-02.pkl to DB...
2025-05-07 22:26:18 - ERROR - DB load error for ga_sessions_new_2022-01-02.pkl: 'Engine' object has no attribute 'cursor'
2025-05-07 22:26:34 - ERROR - Failed to send log to Elasticsearch: Connection error caused by: ConnectionError(Connection error caused by: NewConnectionError(<urllib3.connection.HTTPConnection object at 0x000001C9399CBD60>: Failed to establish a new connection: [Errno 11001] getaddrinfo failed))
2025-05-07 22:26:51 - INFO - ETL process started
2025-05-07 22:27:00 - ERROR - Failed to send log to Elasticsearch: Connection error caused by: ConnectionError(Connection error caused by: NewConnectionError(<urllib3.connection.HTTPConnection object at 0x000001C939BE9690>: Failed to establish a new connection: [Errno 11001] getaddrinfo failed))
2025-05-07 22:27:07 - ERROR - Failed to send log to Elasticsearch: Connection error caused by: ConnectionError(Connection error caused by: NewConnectionError(<urllib3.connection.HTTPConnection object at 0x000001C55C2919F0>: Failed to establish a new connection: [Errno 11001] getaddrinfo failed))
2025-05-07 22:27:26 - ERROR - Failed to send log to Elasticsearch: Connection error caused by: ConnectionError(Connection error caused by: NewConnectionError(<urllib3.connection.HTTPConnection object at 0x000001C939BEB130>: Failed to establish a new connection: [Errno 11001] getaddrinfo failed))
2025-05-07 22:27:34 - ERROR - Failed to send log to Elasticsearch: Connection error caused by: ConnectionError(Connection error caused by: NewConnectionError(<urllib3.connection.HTTPConnection object at 0x000001C55C292B30>: Failed to establish a new connection: [Errno 11001] getaddrinfo failed))
2025-05-07 22:27:53 - ERROR - Failed to send log to Elasticsearch: Connection error caused by: ConnectionError(Connection error caused by: NewConnectionError(<urllib3.connection.HTTPConnection object at 0x000001C939BE9B70>: Failed to establish a new connection: [Errno 11001] getaddrinfo failed))
2025-05-07 22:28:00 - ERROR - Failed to send log to Elasticsearch: Connection error caused by: ConnectionError(Connection error caused by: NewConnectionError(<urllib3.connection.HTTPConnection object at 0x000001C55C293C10>: Failed to establish a new connection: [Errno 11001] getaddrinfo failed))
2025-05-07 22:28:19 - ERROR - Failed to send log to Elasticsearch: Connection error caused by: ConnectionError(Connection error caused by: NewConnectionError(<urllib3.connection.HTTPConnection object at 0x000001C939BEC7F0>: Failed to establish a new connection: [Errno 11001] getaddrinfo failed))
2025-05-07 22:28:19 - ERROR - Failed to send log to Elasticsearch: RetryError[<Future at 0x1c9399cbbb0 state=finished raised ConnectionError>]
2025-05-07 22:28:26 - ERROR - Failed to send log to Elasticsearch: Connection error caused by: ConnectionError(Connection error caused by: NewConnectionError(<urllib3.connection.HTTPConnection object at 0x000001C55C292B30>: Failed to establish a new connection: [Errno 11001] getaddrinfo failed))
2025-05-07 22:28:52 - ERROR - Failed to send log to Elasticsearch: Connection error caused by: ConnectionError(Connection error caused by: NewConnectionError(<urllib3.connection.HTTPConnection object at 0x000001C55C293EB0>: Failed to establish a new connection: [Errno 11001] getaddrinfo failed))
2025-05-07 22:28:52 - ERROR - Failed to send log to Elasticsearch: RetryError[<Future at 0x1c55c292d70 state=finished raised ConnectionError>]
2025-05-07 22:28:52 - INFO - Sending ga_sessions_new_2022-01-02.pkl to DB...
2025-05-07 22:28:52 - ERROR - DB load error for ga_sessions_new_2022-01-02.pkl: 'Engine' object has no attribute 'cursor'
2025-05-07 22:29:09 - ERROR - Failed to send log to Elasticsearch: Connection error caused by: ConnectionError(Connection error caused by: NewConnectionError(<urllib3.connection.HTTPConnection object at 0x000001C55C385840>: Failed to establish a new connection: [Errno 11001] getaddrinfo failed))
2025-05-07 22:29:35 - ERROR - Failed to send log to Elasticsearch: Connection error caused by: ConnectionError(Connection error caused by: NewConnectionError(<urllib3.connection.HTTPConnection object at 0x000001C55C386620>: Failed to establish a new connection: [Errno 11001] getaddrinfo failed))
2025-05-07 22:30:01 - ERROR - Failed to send log to Elasticsearch: Connection error caused by: ConnectionError(Connection error caused by: NewConnectionError(<urllib3.connection.HTTPConnection object at 0x000001C55C387370>: Failed to establish a new connection: [Errno 11001] getaddrinfo failed))
2025-05-07 22:30:27 - ERROR - Failed to send log to Elasticsearch: Connection error caused by: ConnectionError(Connection error caused by: NewConnectionError(<urllib3.connection.HTTPConnection object at 0x000001C55C3865F0>: Failed to establish a new connection: [Errno 11001] getaddrinfo failed))
2025-05-07 22:30:54 - ERROR - Failed to send log to Elasticsearch: Connection error caused by: ConnectionError(Connection error caused by: NewConnectionError(<urllib3.connection.HTTPConnection object at 0x000001C55C387EB0>: Failed to establish a new connection: [Errno 11001] getaddrinfo failed))
2025-05-07 22:30:54 - ERROR - Failed to send log to Elasticsearch: RetryError[<Future at 0x1c55c387c40 state=finished raised ConnectionError>]
2025-05-07 22:30:54 - ERROR - ETL process crashed: 'Engine' object has no attribute 'cursor'
2025-05-07 22:31:10 - ERROR - Failed to send log to Elasticsearch: Connection error caused by: ConnectionError(Connection error caused by: NewConnectionError(<urllib3.connection.HTTPConnection object at 0x000001C55C386890>: Failed to establish a new connection: [Errno 11001] getaddrinfo failed))
2025-05-07 22:31:36 - ERROR - Failed to send log to Elasticsearch: Connection error caused by: ConnectionError(Connection error caused by: NewConnectionError(<urllib3.connection.HTTPConnection object at 0x000001C55C570B20>: Failed to establish a new connection: [Errno 11001] getaddrinfo failed))
2025-05-09 14:55:39 - INFO - ETL process started
2025-05-09 14:55:55 - ERROR - Failed to send log to Elasticsearch: Connection error caused by: ConnectionError(Connection error caused by: NameResolutionError(<urllib3.connection.HTTPConnection object at 0x0000022B02EEB850>: Failed to resolve 'elasticsearch' ([Errno 11001] getaddrinfo failed)))
2025-05-09 14:56:21 - ERROR - Failed to send log to Elasticsearch: Connection error caused by: ConnectionError(Connection error caused by: NameResolutionError(<urllib3.connection.HTTPConnection object at 0x0000022B02EEBD00>: Failed to resolve 'elasticsearch' ([Errno 11001] getaddrinfo failed)))
2025-05-09 14:56:48 - ERROR - Failed to send log to Elasticsearch: Connection error caused by: ConnectionError(Connection error caused by: NameResolutionError(<urllib3.connection.HTTPConnection object at 0x0000022B02F409D0>: Failed to resolve 'elasticsearch' ([Errno 11001] getaddrinfo failed)))
2025-05-09 14:57:14 - ERROR - Failed to send log to Elasticsearch: Connection error caused by: ConnectionError(Connection error caused by: NameResolutionError(<urllib3.connection.HTTPConnection object at 0x0000022B02EEB910>: Failed to resolve 'elasticsearch' ([Errno 11001] getaddrinfo failed)))
2025-05-09 14:57:40 - ERROR - Failed to send log to Elasticsearch: Connection error caused by: ConnectionError(Connection error caused by: NameResolutionError(<urllib3.connection.HTTPConnection object at 0x0000022B02F41270>: Failed to resolve 'elasticsearch' ([Errno 11001] getaddrinfo failed)))
2025-05-09 14:57:40 - ERROR - Failed to send log to Elasticsearch: RetryError[<Future at 0x22b02eeb4c0 state=finished raised ConnectionError>]
2025-05-09 14:57:40 - INFO - Sending ga_sessions_new_2022-01-02.pkl to DB...
2025-05-09 14:57:40 - ERROR - DB load error for ga_sessions_new_2022-01-02.pkl: No module named 'numpy._core'
2025-05-09 14:57:56 - ERROR - Failed to send log to Elasticsearch: Connection error caused by: ConnectionError(Connection error caused by: NameResolutionError(<urllib3.connection.HTTPConnection object at 0x0000022B03010640>: Failed to resolve 'elasticsearch' ([Errno 11001] getaddrinfo failed)))
2025-05-09 14:58:22 - ERROR - Failed to send log to Elasticsearch: Connection error caused by: ConnectionError(Connection error caused by: NameResolutionError(<urllib3.connection.HTTPConnection object at 0x0000022B03011630>: Failed to resolve 'elasticsearch' ([Errno 11001] getaddrinfo failed)))
2025-05-09 14:58:49 - ERROR - Failed to send log to Elasticsearch: Connection error caused by: ConnectionError(Connection error caused by: NameResolutionError(<urllib3.connection.HTTPConnection object at 0x0000022B03012710>: Failed to resolve 'elasticsearch' ([Errno 11001] getaddrinfo failed)))
2025-05-09 14:59:15 - ERROR - Failed to send log to Elasticsearch: Connection error caused by: ConnectionError(Connection error caused by: NameResolutionError(<urllib3.connection.HTTPConnection object at 0x0000022B03011870>: Failed to resolve 'elasticsearch' ([Errno 11001] getaddrinfo failed)))
2025-05-09 14:59:41 - ERROR - Failed to send log to Elasticsearch: Connection error caused by: ConnectionError(Connection error caused by: NameResolutionError(<urllib3.connection.HTTPConnection object at 0x0000022B03013580>: Failed to resolve 'elasticsearch' ([Errno 11001] getaddrinfo failed)))
2025-05-09 14:59:41 - ERROR - Failed to send log to Elasticsearch: RetryError[<Future at 0x22b02fde9e0 state=finished raised ConnectionError>]
2025-05-09 14:59:41 - ERROR - ETL process crashed: No module named 'numpy._core'
2025-05-09 14:59:57 - ERROR - Failed to send log to Elasticsearch: Connection error caused by: ConnectionError(Connection error caused by: NameResolutionError(<urllib3.connection.HTTPConnection object at 0x0000022B03011570>: Failed to resolve 'elasticsearch' ([Errno 11001] getaddrinfo failed)))
2025-05-09 15:00:24 - ERROR - Failed to send log to Elasticsearch: Connection error caused by: ConnectionError(Connection error caused by: NameResolutionError(<urllib3.connection.HTTPConnection object at 0x0000022B0305C550>: Failed to resolve 'elasticsearch' ([Errno 11001] getaddrinfo failed)))
2025-05-09 15:00:50 - ERROR - Failed to send log to Elasticsearch: Connection error caused by: ConnectionError(Connection error caused by: NameResolutionError(<urllib3.connection.HTTPConnection object at 0x0000022B03011870>: Failed to resolve 'elasticsearch' ([Errno 11001] getaddrinfo failed)))
2025-05-09 15:01:16 - ERROR - Failed to send log to Elasticsearch: Connection error caused by: ConnectionError(Connection error caused by: NameResolutionError(<urllib3.connection.HTTPConnection object at 0x0000022B03013580>: Failed to resolve 'elasticsearch' ([Errno 11001] getaddrinfo failed)))
2025-05-09 15:01:42 - ERROR - Failed to send log to Elasticsearch: Connection error caused by: ConnectionError(Connection error caused by: NameResolutionError(<urllib3.connection.HTTPConnection object at 0x0000022B03012AD0>: Failed to resolve 'elasticsearch' ([Errno 11001] getaddrinfo failed)))
2025-05-09 15:01:42 - ERROR - Failed to send log to Elasticsearch: RetryError[<Future at 0x22b030126e0 state=finished raised ConnectionError>]
2025-05-09 15:04:24 - INFO - ETL process started
2025-05-09 15:04:40 - ERROR - Failed to send log to Elasticsearch: Connection error caused by: ConnectionError(Connection error caused by: NameResolutionError(<urllib3.connection.HTTPConnection object at 0x0000028B6E2AB850>: Failed to resolve 'elasticsearch' ([Errno 11001] getaddrinfo failed)))
2025-05-09 15:05:07 - ERROR - Failed to send log to Elasticsearch: Connection error caused by: ConnectionError(Connection error caused by: NameResolutionError(<urllib3.connection.HTTPConnection object at 0x0000028B6E2ABD00>: Failed to resolve 'elasticsearch' ([Errno 11001] getaddrinfo failed)))
2025-05-09 15:05:33 - ERROR - Failed to send log to Elasticsearch: Connection error caused by: ConnectionError(Connection error caused by: NameResolutionError(<urllib3.connection.HTTPConnection object at 0x0000028B6E3009D0>: Failed to resolve 'elasticsearch' ([Errno 11001] getaddrinfo failed)))
2025-05-09 15:05:59 - ERROR - Failed to send log to Elasticsearch: Connection error caused by: ConnectionError(Connection error caused by: NameResolutionError(<urllib3.connection.HTTPConnection object at 0x0000028B6E2AB910>: Failed to resolve 'elasticsearch' ([Errno 11001] getaddrinfo failed)))
2025-05-09 15:06:25 - ERROR - Failed to send log to Elasticsearch: Connection error caused by: ConnectionError(Connection error caused by: NameResolutionError(<urllib3.connection.HTTPConnection object at 0x0000028B6E301270>: Failed to resolve 'elasticsearch' ([Errno 11001] getaddrinfo failed)))
2025-05-09 15:06:25 - ERROR - Failed to send log to Elasticsearch: RetryError[<Future at 0x28b6e2ab4c0 state=finished raised ConnectionError>]
2025-05-09 15:06:25 - INFO - Sending ga_sessions_new_2022-01-02.pkl to DB...
2025-05-09 15:06:25 - ERROR - DB load error for ga_sessions_new_2022-01-02.pkl: No module named 'numpy._core'
2025-05-09 15:06:42 - ERROR - Failed to send log to Elasticsearch: Connection error caused by: ConnectionError(Connection error caused by: NameResolutionError(<urllib3.connection.HTTPConnection object at 0x0000028B6E3CC640>: Failed to resolve 'elasticsearch' ([Errno 11001] getaddrinfo failed)))
2025-05-09 15:07:08 - ERROR - Failed to send log to Elasticsearch: Connection error caused by: ConnectionError(Connection error caused by: NameResolutionError(<urllib3.connection.HTTPConnection object at 0x0000028B6E3CD630>: Failed to resolve 'elasticsearch' ([Errno 11001] getaddrinfo failed)))
2025-05-09 15:07:34 - ERROR - Failed to send log to Elasticsearch: Connection error caused by: ConnectionError(Connection error caused by: NameResolutionError(<urllib3.connection.HTTPConnection object at 0x0000028B6E3CE710>: Failed to resolve 'elasticsearch' ([Errno 11001] getaddrinfo failed)))
2025-05-09 15:08:00 - ERROR - Failed to send log to Elasticsearch: Connection error caused by: ConnectionError(Connection error caused by: NameResolutionError(<urllib3.connection.HTTPConnection object at 0x0000028B6E3CD870>: Failed to resolve 'elasticsearch' ([Errno 11001] getaddrinfo failed)))
2025-05-09 15:08:26 - ERROR - Failed to send log to Elasticsearch: Connection error caused by: ConnectionError(Connection error caused by: NameResolutionError(<urllib3.connection.HTTPConnection object at 0x0000028B6E3CF580>: Failed to resolve 'elasticsearch' ([Errno 11001] getaddrinfo failed)))
2025-05-09 15:08:26 - ERROR - Failed to send log to Elasticsearch: RetryError[<Future at 0x28b6e39e9e0 state=finished raised ConnectionError>]
2025-05-09 15:08:26 - ERROR - ETL process crashed: No module named 'numpy._core'
2025-05-09 15:08:42 - ERROR - Failed to send log to Elasticsearch: Connection error caused by: ConnectionError(Connection error caused by: NameResolutionError(<urllib3.connection.HTTPConnection object at 0x0000028B6E3CD570>: Failed to resolve 'elasticsearch' ([Errno 11001] getaddrinfo failed)))
2025-05-09 15:09:09 - ERROR - Failed to send log to Elasticsearch: Connection error caused by: ConnectionError(Connection error caused by: NameResolutionError(<urllib3.connection.HTTPConnection object at 0x0000028B6E41C550>: Failed to resolve 'elasticsearch' ([Errno 11001] getaddrinfo failed)))
2025-05-09 15:09:35 - ERROR - Failed to send log to Elasticsearch: Connection error caused by: ConnectionError(Connection error caused by: NameResolutionError(<urllib3.connection.HTTPConnection object at 0x0000028B6E3CD870>: Failed to resolve 'elasticsearch' ([Errno 11001] getaddrinfo failed)))
2025-05-09 15:12:05 - WARNING - File ga_sessions_new_2022-01-01.json contains no valid sessions. Skipping.
2025-05-09 15:12:21 - ERROR - Failed to send log to Elasticsearch: Connection error caused by: ConnectionError(Connection error caused by: NameResolutionError(<urllib3.connection.HTTPConnection object at 0x00000190BBCBAF20>: Failed to resolve 'elasticsearch' ([Errno 11001] getaddrinfo failed)))
2025-05-09 15:12:47 - ERROR - Failed to send log to Elasticsearch: Connection error caused by: ConnectionError(Connection error caused by: NameResolutionError(<urllib3.connection.HTTPConnection object at 0x00000190BBCBBFD0>: Failed to resolve 'elasticsearch' ([Errno 11001] getaddrinfo failed)))
2025-05-09 15:13:14 - ERROR - Failed to send log to Elasticsearch: Connection error caused by: ConnectionError(Connection error caused by: NameResolutionError(<urllib3.connection.HTTPConnection object at 0x00000190BBCF90F0>: Failed to resolve 'elasticsearch' ([Errno 11001] getaddrinfo failed)))
2025-05-09 15:13:40 - ERROR - Failed to send log to Elasticsearch: Connection error caused by: ConnectionError(Connection error caused by: NameResolutionError(<urllib3.connection.HTTPConnection object at 0x00000190BBCF8670>: Failed to resolve 'elasticsearch' ([Errno 11001] getaddrinfo failed)))
2025-05-09 15:14:06 - ERROR - Failed to send log to Elasticsearch: Connection error caused by: ConnectionError(Connection error caused by: NameResolutionError(<urllib3.connection.HTTPConnection object at 0x00000190BBCFA1D0>: Failed to resolve 'elasticsearch' ([Errno 11001] getaddrinfo failed)))
2025-05-09 15:14:06 - ERROR - Failed to send log to Elasticsearch: RetryError[<Future at 0x190bbcbbdc0 state=finished raised ConnectionError>]
2025-05-09 15:14:06 - INFO - Transformed data saved to C:\Users\Ekaterina\sber_de\de_for_sber\data\processed\new_sessions\ga_sessions_new_2022-01-02.pkl
2025-05-09 15:14:06 - INFO - All files have been processed.
2025-05-09 15:14:07 - WARNING - File ga_sessions_new_2022-01-01.json contains no valid sessions. Skipping.
2025-05-09 15:14:23 - ERROR - Failed to send log to Elasticsearch: Connection error caused by: ConnectionError(Connection error caused by: NameResolutionError(<urllib3.connection.HTTPConnection object at 0x00000190BC59E6E0>: Failed to resolve 'elasticsearch' ([Errno 11001] getaddrinfo failed)))
2025-05-09 15:14:49 - ERROR - Failed to send log to Elasticsearch: Connection error caused by: ConnectionError(Connection error caused by: NameResolutionError(<urllib3.connection.HTTPConnection object at 0x00000190BC59F880>: Failed to resolve 'elasticsearch' ([Errno 11001] getaddrinfo failed)))
2025-05-09 15:15:15 - ERROR - Failed to send log to Elasticsearch: Connection error caused by: ConnectionError(Connection error caused by: NameResolutionError(<urllib3.connection.HTTPConnection object at 0x00000190BC59EB00>: Failed to resolve 'elasticsearch' ([Errno 11001] getaddrinfo failed)))
2025-05-09 15:15:41 - ERROR - Failed to send log to Elasticsearch: Connection error caused by: ConnectionError(Connection error caused by: NameResolutionError(<urllib3.connection.HTTPConnection object at 0x00000190BC5D49A0>: Failed to resolve 'elasticsearch' ([Errno 11001] getaddrinfo failed)))
2025-05-09 15:16:07 - ERROR - Failed to send log to Elasticsearch: Connection error caused by: ConnectionError(Connection error caused by: NameResolutionError(<urllib3.connection.HTTPConnection object at 0x00000190BC59ED10>: Failed to resolve 'elasticsearch' ([Errno 11001] getaddrinfo failed)))
2025-05-09 15:16:07 - ERROR - Failed to send log to Elasticsearch: RetryError[<Future at 0x190bc59eb30 state=finished raised ConnectionError>]
2025-05-09 15:16:07 - WARNING - File ga_sessions_new_2022-01-02.json has already been loaded. Skipping.
2025-05-09 15:16:24 - ERROR - Failed to send log to Elasticsearch: Connection error caused by: ConnectionError(Connection error caused by: NameResolutionError(<urllib3.connection.HTTPConnection object at 0x00000190BC5D45E0>: Failed to resolve 'elasticsearch' ([Errno 11001] getaddrinfo failed)))
2025-05-09 15:22:47 - WARNING - File ga_sessions_new_2022-01-01.json contains no valid sessions. Skipping.
2025-05-09 15:23:03 - ERROR - Failed to send log to Elasticsearch: Connection error caused by: ConnectionError(Connection error caused by: NameResolutionError(<urllib3.connection.HTTPConnection object at 0x0000027AEFE33D90>: Failed to resolve 'elasticsearch' ([Errno 11001] getaddrinfo failed)))
2025-05-09 15:23:30 - ERROR - Failed to send log to Elasticsearch: Connection error caused by: ConnectionError(Connection error caused by: NameResolutionError(<urllib3.connection.HTTPConnection object at 0x0000027AEFE32230>: Failed to resolve 'elasticsearch' ([Errno 11001] getaddrinfo failed)))
2025-05-09 15:24:00 - WARNING - File ga_sessions_new_2022-01-01.json contains no valid sessions. Skipping.
2025-05-09 15:24:16 - ERROR - Failed to send log to Elasticsearch: Connection error caused by: ConnectionError(Connection error caused by: NameResolutionError(<urllib3.connection.HTTPConnection object at 0x0000029F82E6AEF0>: Failed to resolve 'elasticsearch' ([Errno 11001] getaddrinfo failed)))
2025-05-09 15:24:16 - ERROR - Failed to send log to Elasticsearch: RetryError[<Future at 0x29f82e6abc0 state=finished raised ConnectionError>]
2025-05-09 15:24:16 - INFO - Transformed data saved to C:\Users\Ekaterina\sber_de\de_for_sber\data\processed\new_sessions\ga_sessions_new_2022-01-02.pkl
2025-05-09 15:24:16 - INFO - All files have been processed.
2025-05-09 15:24:16 - INFO - Sending ga_sessions_new_2022-01-02.pkl to DB...
2025-05-09 15:24:16 - ERROR - DB load error for ga_sessions_new_2022-01-02.pkl: 'Engine' object has no attribute 'cursor'
2025-05-09 15:24:32 - ERROR - Failed to send log to Elasticsearch: Connection error caused by: ConnectionError(Connection error caused by: NameResolutionError(<urllib3.connection.HTTPConnection object at 0x0000029F838F7E20>: Failed to resolve 'elasticsearch' ([Errno 11001] getaddrinfo failed)))
2025-05-09 15:24:32 - ERROR - Failed to send log to Elasticsearch: RetryError[<Future at 0x29f838f0ee0 state=finished raised ConnectionError>]
2025-05-09 15:26:13 - WARNING - File ga_sessions_new_2022-01-01.json contains no valid sessions. Skipping.
2025-05-09 15:26:29 - ERROR - Failed to send log to Elasticsearch: Connection error caused by: ConnectionError(Connection error caused by: NameResolutionError(<urllib3.connection.HTTPConnection object at 0x0000023452103CA0>: Failed to resolve 'elasticsearch' ([Errno 11001] getaddrinfo failed)))
2025-05-09 15:26:29 - ERROR - Failed to send log to Elasticsearch: RetryError[<Future at 0x234521034c0 state=finished raised ConnectionError>]
2025-05-09 15:26:29 - WARNING - File ga_sessions_new_2022-01-02.json has already been loaded. Skipping.
2025-05-09 15:26:45 - ERROR - Failed to send log to Elasticsearch: Connection error caused by: ConnectionError(Connection error caused by: NameResolutionError(<urllib3.connection.HTTPConnection object at 0x0000023452102110>: Failed to resolve 'elasticsearch' ([Errno 11001] getaddrinfo failed)))
2025-05-09 15:26:45 - ERROR - Failed to send log to Elasticsearch: RetryError[<Future at 0x234521023e0 state=finished raised ConnectionError>]
2025-05-09 15:26:45 - INFO - All files have been processed.
2025-05-09 15:26:45 - INFO - Sending ga_sessions_new_2022-01-02.pkl to DB...
2025-05-09 15:26:48 - ERROR - DB load error for ga_sessions_new_2022-01-02.pkl: (psycopg2.OperationalError) could not translate host name "postgres" to address: No such host is known. 

(Background on this error at: https://sqlalche.me/e/14/e3q8)
2025-05-09 15:27:04 - ERROR - Failed to send log to Elasticsearch: Connection error caused by: ConnectionError(Connection error caused by: NameResolutionError(<urllib3.connection.HTTPConnection object at 0x000002345219BD30>: Failed to resolve 'elasticsearch' ([Errno 11001] getaddrinfo failed)))
2025-05-09 15:27:04 - ERROR - Failed to send log to Elasticsearch: RetryError[<Future at 0x2345219b9a0 state=finished raised ConnectionError>]
2025-05-09 15:28:52 - WARNING - File ga_sessions_new_2022-01-01.json contains no valid sessions. Skipping.
2025-05-09 15:29:08 - ERROR - Failed to send log to Elasticsearch: Connection error caused by: ConnectionError(Connection error caused by: NameResolutionError(<urllib3.connection.HTTPConnection object at 0x000001450CDD3CA0>: Failed to resolve 'elasticsearch' ([Errno 11001] getaddrinfo failed)))
2025-05-09 15:29:08 - ERROR - Failed to send log to Elasticsearch: RetryError[<Future at 0x1450cdd37f0 state=finished raised ConnectionError>]
2025-05-09 15:29:08 - WARNING - File ga_sessions_new_2022-01-02.json has already been loaded. Skipping.
2025-05-09 15:29:24 - ERROR - Failed to send log to Elasticsearch: Connection error caused by: ConnectionError(Connection error caused by: NameResolutionError(<urllib3.connection.HTTPConnection object at 0x000001450CDD2110>: Failed to resolve 'elasticsearch' ([Errno 11001] getaddrinfo failed)))
2025-05-09 15:29:24 - ERROR - Failed to send log to Elasticsearch: RetryError[<Future at 0x1450cdd23e0 state=finished raised ConnectionError>]
2025-05-09 15:29:24 - INFO - All files have been processed.
2025-05-09 15:29:24 - INFO - Sending ga_sessions_new_2022-01-02.pkl to DB...
2025-05-09 15:29:24 - ERROR - DB load error for ga_sessions_new_2022-01-02.pkl: 'Connection' object has no attribute 'cursor'
2025-05-09 15:29:41 - ERROR - Failed to send log to Elasticsearch: Connection error caused by: ConnectionError(Connection error caused by: NameResolutionError(<urllib3.connection.HTTPConnection object at 0x000001450CE6B9D0>: Failed to resolve 'elasticsearch' ([Errno 11001] getaddrinfo failed)))
2025-05-09 15:29:41 - ERROR - Failed to send log to Elasticsearch: RetryError[<Future at 0x1450a23bf70 state=finished raised ConnectionError>]
2025-05-09 15:31:27 - WARNING - File ga_sessions_new_2022-01-01.json contains no valid sessions. Skipping.
2025-05-09 15:31:43 - ERROR - Failed to send log to Elasticsearch: Connection error caused by: ConnectionError(Connection error caused by: NameResolutionError(<urllib3.connection.HTTPConnection object at 0x0000027A29353D60>: Failed to resolve 'elasticsearch' ([Errno 11001] getaddrinfo failed)))
2025-05-09 15:31:43 - ERROR - Failed to send log to Elasticsearch: RetryError[<Future at 0x27a293538b0 state=finished raised ConnectionError>]
2025-05-09 15:31:43 - WARNING - File ga_sessions_new_2022-01-02.json has already been loaded. Skipping.
2025-05-09 15:31:59 - ERROR - Failed to send log to Elasticsearch: Connection error caused by: ConnectionError(Connection error caused by: NameResolutionError(<urllib3.connection.HTTPConnection object at 0x0000027A29352110>: Failed to resolve 'elasticsearch' ([Errno 11001] getaddrinfo failed)))
2025-05-09 15:31:59 - ERROR - Failed to send log to Elasticsearch: RetryError[<Future at 0x27a293523e0 state=finished raised ConnectionError>]
2025-05-09 15:31:59 - INFO - All files have been processed.
2025-05-09 15:31:59 - INFO - Sending ga_sessions_new_2022-01-02.pkl to DB...
2025-05-09 15:31:59 - ERROR - DB load error for ga_sessions_new_2022-01-02.pkl: 'Engine' object has no attribute 'cursor'
2025-05-09 15:32:15 - ERROR - Failed to send log to Elasticsearch: Connection error caused by: ConnectionError(Connection error caused by: NameResolutionError(<urllib3.connection.HTTPConnection object at 0x0000027A293EBA00>: Failed to resolve 'elasticsearch' ([Errno 11001] getaddrinfo failed)))
2025-05-09 15:32:15 - ERROR - Failed to send log to Elasticsearch: RetryError[<Future at 0x27a146968c0 state=finished raised ConnectionError>]
2025-05-09 15:53:51 - WARNING - File ga_sessions_new_2022-01-01.json contains no valid sessions. Skipping.
2025-05-09 15:54:07 - ERROR - Failed to send log to Elasticsearch: Connection error caused by: ConnectionError(Connection error caused by: NameResolutionError(<urllib3.connection.HTTPConnection object at 0x0000019A4A45E860>: Failed to resolve 'elasticsearch' ([Errno 11001] getaddrinfo failed)))
2025-05-09 15:54:07 - ERROR - Failed to send log to Elasticsearch: RetryError[<Future at 0x19a4a45e530 state=finished raised ConnectionError>]
2025-05-09 15:54:07 - WARNING - File ga_sessions_new_2022-01-02.json has already been loaded. Skipping.
2025-05-09 15:54:23 - ERROR - Failed to send log to Elasticsearch: Connection error caused by: ConnectionError(Connection error caused by: NameResolutionError(<urllib3.connection.HTTPConnection object at 0x0000019A4A45FA30>: Failed to resolve 'elasticsearch' ([Errno 11001] getaddrinfo failed)))
2025-05-09 15:54:23 - ERROR - Failed to send log to Elasticsearch: RetryError[<Future at 0x19a4a45f760 state=finished raised ConnectionError>]
2025-05-09 15:54:23 - INFO - All files have been processed.
2025-05-09 15:54:23 - INFO - Sending ga_sessions_new_2022-01-02.pkl to DB...
2025-05-09 15:54:23 - ERROR - DB load error for ga_sessions_new_2022-01-02.pkl: 'Engine' object has no attribute 'cursor'
2025-05-09 15:54:39 - ERROR - Failed to send log to Elasticsearch: Connection error caused by: ConnectionError(Connection error caused by: NameResolutionError(<urllib3.connection.HTTPConnection object at 0x0000019A4A52F3A0>: Failed to resolve 'elasticsearch' ([Errno 11001] getaddrinfo failed)))
2025-05-09 15:54:39 - ERROR - Failed to send log to Elasticsearch: RetryError[<Future at 0x19a4a52f220 state=finished raised ConnectionError>]
2025-05-09 15:57:17 - WARNING - File ga_sessions_new_2022-01-01.json contains no valid sessions. Skipping.
2025-05-09 15:57:34 - ERROR - Failed to send log to Elasticsearch: Connection error caused by: ConnectionError(Connection error caused by: NameResolutionError(<urllib3.connection.HTTPConnection object at 0x0000027B4639B4F0>: Failed to resolve 'elasticsearch' ([Errno 11001] getaddrinfo failed)))
2025-05-09 15:57:34 - ERROR - Failed to send log to Elasticsearch: RetryError[<Future at 0x27b4639b040 state=finished raised ConnectionError>]
2025-05-09 15:57:34 - WARNING - File ga_sessions_new_2022-01-02.json has already been loaded. Skipping.
2025-05-09 15:57:50 - ERROR - Failed to send log to Elasticsearch: Connection error caused by: ConnectionError(Connection error caused by: NameResolutionError(<urllib3.connection.HTTPConnection object at 0x0000027B4639A110>: Failed to resolve 'elasticsearch' ([Errno 11001] getaddrinfo failed)))
2025-05-09 15:57:50 - ERROR - Failed to send log to Elasticsearch: RetryError[<Future at 0x27b4639a3e0 state=finished raised ConnectionError>]
2025-05-09 15:57:50 - INFO - All files have been processed.
2025-05-09 15:57:50 - INFO - Sending ga_sessions_new_2022-01-02.pkl to DB...
2025-05-09 15:57:50 - ERROR - DB load error for ga_sessions_new_2022-01-02.pkl: 'Connection' object has no attribute 'cursor'
2025-05-09 15:58:06 - ERROR - Failed to send log to Elasticsearch: Connection error caused by: ConnectionError(Connection error caused by: NameResolutionError(<urllib3.connection.HTTPConnection object at 0x0000027B4643DDE0>: Failed to resolve 'elasticsearch' ([Errno 11001] getaddrinfo failed)))
2025-05-09 15:58:06 - ERROR - Failed to send log to Elasticsearch: RetryError[<Future at 0x27b4643d3f0 state=finished raised ConnectionError>]
2025-05-09 15:59:37 - WARNING - File ga_sessions_new_2022-01-01.json contains no valid sessions. Skipping.
2025-05-09 15:59:54 - ERROR - Failed to send log to Elasticsearch: Connection error caused by: ConnectionError(Connection error caused by: NameResolutionError(<urllib3.connection.HTTPConnection object at 0x00000227BA58B5B0>: Failed to resolve 'elasticsearch' ([Errno 11001] getaddrinfo failed)))
2025-05-09 15:59:54 - ERROR - Failed to send log to Elasticsearch: RetryError[<Future at 0x227ba58b100 state=finished raised ConnectionError>]
2025-05-09 15:59:54 - WARNING - File ga_sessions_new_2022-01-02.json has already been loaded. Skipping.
2025-05-09 16:00:10 - ERROR - Failed to send log to Elasticsearch: Connection error caused by: ConnectionError(Connection error caused by: NameResolutionError(<urllib3.connection.HTTPConnection object at 0x00000227BA58A110>: Failed to resolve 'elasticsearch' ([Errno 11001] getaddrinfo failed)))
2025-05-09 16:00:10 - ERROR - Failed to send log to Elasticsearch: RetryError[<Future at 0x227ba58a3e0 state=finished raised ConnectionError>]
2025-05-09 16:00:10 - INFO - All files have been processed.
2025-05-09 16:00:10 - INFO - Sending ga_sessions_new_2022-01-02.pkl to DB...
2025-05-09 16:00:10 - ERROR - DB load error for ga_sessions_new_2022-01-02.pkl: __enter__
2025-05-09 16:00:26 - ERROR - Failed to send log to Elasticsearch: Connection error caused by: ConnectionError(Connection error caused by: NameResolutionError(<urllib3.connection.HTTPConnection object at 0x00000227BA62F100>: Failed to resolve 'elasticsearch' ([Errno 11001] getaddrinfo failed)))
2025-05-09 16:00:26 - ERROR - Failed to send log to Elasticsearch: RetryError[<Future at 0x227ba62dd20 state=finished raised ConnectionError>]
2025-05-09 16:01:21 - WARNING - File ga_sessions_new_2022-01-01.json contains no valid sessions. Skipping.
2025-05-09 16:01:37 - ERROR - Failed to send log to Elasticsearch: Connection error caused by: ConnectionError(Connection error caused by: NameResolutionError(<urllib3.connection.HTTPConnection object at 0x000002435341B490>: Failed to resolve 'elasticsearch' ([Errno 11001] getaddrinfo failed)))
2025-05-09 16:01:37 - ERROR - Failed to send log to Elasticsearch: RetryError[<Future at 0x2435341afe0 state=finished raised ConnectionError>]
2025-05-09 16:01:37 - WARNING - File ga_sessions_new_2022-01-02.json has already been loaded. Skipping.
2025-05-09 16:01:53 - ERROR - Failed to send log to Elasticsearch: Connection error caused by: ConnectionError(Connection error caused by: NameResolutionError(<urllib3.connection.HTTPConnection object at 0x000002435341A110>: Failed to resolve 'elasticsearch' ([Errno 11001] getaddrinfo failed)))
2025-05-09 16:01:53 - ERROR - Failed to send log to Elasticsearch: RetryError[<Future at 0x2435341a3e0 state=finished raised ConnectionError>]
2025-05-09 16:01:53 - INFO - All files have been processed.
2025-05-09 16:01:53 - INFO - Sending ga_sessions_new_2022-01-02.pkl to DB...
2025-05-09 16:01:54 - ERROR - DB load error for ga_sessions_new_2022-01-02.pkl: Execution failed on sql '
        SELECT
            name
        FROM
            sqlite_master
        WHERE
            type IN ('table', 'view')
            AND name=?;
        ': syntax error at or near ";"
LINE 8:             AND name=?;
                              ^

2025-05-09 16:02:10 - ERROR - Failed to send log to Elasticsearch: Connection error caused by: ConnectionError(Connection error caused by: NameResolutionError(<urllib3.connection.HTTPConnection object at 0x00000243534BF3D0>: Failed to resolve 'elasticsearch' ([Errno 11001] getaddrinfo failed)))
2025-05-09 16:02:10 - ERROR - Failed to send log to Elasticsearch: RetryError[<Future at 0x243534bd390 state=finished raised ConnectionError>]
2025-05-09 16:07:46 - WARNING - File ga_sessions_new_2022-01-01.json contains no valid sessions. Skipping.
2025-05-09 16:08:02 - ERROR - Failed to send log to Elasticsearch: Connection error caused by: ConnectionError(Connection error caused by: NameResolutionError(<urllib3.connection.HTTPConnection object at 0x000002476EC1FE20>: Failed to resolve 'elasticsearch' ([Errno 11001] getaddrinfo failed)))
2025-05-09 16:08:02 - ERROR - Failed to send log to Elasticsearch: RetryError[<Future at 0x2476ec1f970 state=finished raised ConnectionError>]
2025-05-09 16:08:02 - WARNING - File ga_sessions_new_2022-01-02.json has already been loaded. Skipping.
2025-05-09 16:08:18 - ERROR - Failed to send log to Elasticsearch: Connection error caused by: ConnectionError(Connection error caused by: NameResolutionError(<urllib3.connection.HTTPConnection object at 0x000002476EC1E110>: Failed to resolve 'elasticsearch' ([Errno 11001] getaddrinfo failed)))
2025-05-09 16:08:18 - ERROR - Failed to send log to Elasticsearch: RetryError[<Future at 0x2476ec1e3e0 state=finished raised ConnectionError>]
2025-05-09 16:08:18 - INFO - All files have been processed.
2025-05-09 16:08:18 - INFO - Sending ga_sessions_new_2022-01-02.pkl to DB...
2025-05-09 16:08:18 - ERROR - DB load error for ga_sessions_new_2022-01-02.pkl: 'Engine' object has no attribute 'cursor'
2025-05-09 16:08:34 - ERROR - Failed to send log to Elasticsearch: Connection error caused by: ConnectionError(Connection error caused by: NameResolutionError(<urllib3.connection.HTTPConnection object at 0x000002476ECBFC10>: Failed to resolve 'elasticsearch' ([Errno 11001] getaddrinfo failed)))
2025-05-09 16:08:34 - ERROR - Failed to send log to Elasticsearch: RetryError[<Future at 0x2476c042410 state=finished raised ConnectionError>]
2025-05-09 20:28:30 - WARNING - File ga_sessions_new_2022-01-01.json contains no valid sessions. Skipping.
2025-05-09 20:28:46 - ERROR - Failed to send log to Elasticsearch: Connection error caused by: ConnectionError(Connection error caused by: NameResolutionError(<urllib3.connection.HTTPConnection object at 0x000001FA50D580A0>: Failed to resolve 'elasticsearch' ([Errno 11001] getaddrinfo failed)))
2025-05-09 20:28:46 - ERROR - Failed to send log to Elasticsearch: RetryError[<Future at 0x1fa50d2fd30 state=finished raised ConnectionError>]
2025-05-09 20:28:46 - WARNING - File ga_sessions_new_2022-01-02.json has already been loaded. Skipping.
2025-05-09 20:29:03 - ERROR - Failed to send log to Elasticsearch: Connection error caused by: ConnectionError(Connection error caused by: NameResolutionError(<urllib3.connection.HTTPConnection object at 0x000001FA50D59270>: Failed to resolve 'elasticsearch' ([Errno 11001] getaddrinfo failed)))
2025-05-09 20:29:03 - ERROR - Failed to send log to Elasticsearch: RetryError[<Future at 0x1fa50d58fa0 state=finished raised ConnectionError>]
2025-05-09 20:29:03 - INFO - All files have been processed.
2025-05-09 20:29:03 - INFO - Sending ga_sessions_new_2022-01-02.pkl to DB...
2025-05-09 20:29:03 - ERROR - DB load error for ga_sessions_new_2022-01-02.pkl: (psycopg2.errors.UniqueViolation) duplicate key value violates unique constraint "sessions_pkey"
DETAIL:  Key (session_id)=(9055432108483400094.1641140638.1641140638) already exists.

[SQL: INSERT INTO sessions (session_id, client_id, visit_date, visit_time, visit_number, utm_source, utm_medium, utm_campaign, utm_adcontent, utm_keyword, device_category, device_os, device_brand, device_screen_resolution, device_browser, geo_country, geo_city) VALUES (%(session_id)s, %(client_id)s, %(visit_date)s, %(visit_time)s, %(visit_number)s, %(utm_source)s, %(utm_medium)s, %(utm_campaign)s, %(utm_adcontent)s, %(utm_keyword)s, %(device_category)s, %(device_os)s, %(device_brand)s, %(device_screen_resolution)s, %(device_browser)s, %(geo_country)s, %(geo_city)s)]
[parameters: ({'session_id': '9055432108483400094.1641140638.1641140638', 'client_id': '2108382086.1641140638', 'visit_date': datetime.datetime(2022, 1, 2, 0, 0), 'visit_time': datetime.time(19, 23, 58), 'visit_number': 1, 'utm_source': 'hqpYkWpkYefgduliaKcm', 'utm_medium': 'cpc', 'utm_campaign': 'unknown', 'utm_adcontent': 'vmpjxytvOioeqSlwNoAl', 'utm_keyword': 'BhUZBJUdmsWLEISSdxTa', 'device_category': 'mobile', 'device_os': 'Android', 'device_brand': 'Xiaomi', 'device_screen_resolution': '393x851', 'device_browser': 'Android Webview', 'geo_country': 'Russia', 'geo_city': 'Moscow'}, {'session_id': '9056424722670117391.1641112635.1641112635', 'client_id': '2108613197.1641112079', 'visit_date': datetime.datetime(2022, 1, 2, 0, 0), 'visit_time': datetime.time(11, 37, 15), 'visit_number': 1, 'utm_source': 'kVGXyneGKJVfHKWnWbEr', 'utm_medium': '(none)', 'utm_campaign': 'XOywtQLVBIVeKsBULENc', 'utm_adcontent': 'vmpjxytvOioeqSlwNoAl', 'utm_keyword': 'BhUZBJUdmsWLEISSdxTa', 'device_category': 'mobile', 'device_os': 'Android', 'device_brand': 'Lenovo', 'device_screen_resolution': '412x915', 'device_browser': 'Chrome', 'geo_country': 'Russia', 'geo_city': 'Kazan'}, {'session_id': '9058564964994900640.1641153986.1641153986', 'client_id': '2109111511.1632756384', 'visit_date': datetime.datetime(2022, 1, 2, 0, 0), 'visit_time': datetime.time(23, 6, 26), 'visit_number': 2, 'utm_source': 'hqpYkWpkYefgduliaKcm', 'utm_medium': 'cpc', 'utm_campaign': 'unknown', 'utm_adcontent': 'vmpjxytvOioeqSlwNoAl', 'utm_keyword': 'BhUZBJUdmsWLEISSdxTa', 'device_category': 'mobile', 'device_os': 'Android', 'device_brand': 'Samsung', 'device_screen_resolution': '360x740', 'device_browser': 'Android Webview', 'geo_country': 'Russia', 'geo_city': 'Saint Petersburg'}, {'session_id': '9059738831104859637.1641111028.1641111028', 'client_id': '2109384823.1641111029', 'visit_date': datetime.datetime(2022, 1, 2, 0, 0), 'visit_time': datetime.time(11, 10, 28), 'visit_number': 1, 'utm_source': 'sORFTBvqnhWCekwPSNpw', 'utm_medium': 'banner', 'utm_campaign': 'EtfLrwPWorOxUtcoUEYQ', 'utm_adcontent': 'XuLWchPRHivTUPkStLhY', 'utm_keyword': 'BhUZBJUdmsWLEISSdxTa', 'device_category': 'mobile', 'device_os': 'iOS', 'device_brand': 'Apple', 'device_screen_resolution': '414x896', 'device_browser': 'Safari', 'geo_country': 'Russia', 'geo_city': 'Moscow'}, {'session_id': '9060515112083893459.1641131219.1641131219', 'client_id': '2109565565.1641131219', 'visit_date': datetime.datetime(2022, 1, 2, 0, 0), 'visit_time': datetime.time(16, 46, 59), 'visit_number': 1, 'utm_source': 'CVoLfHiSYnQlpfwfKDvK', 'utm_medium': 'cpc', 'utm_campaign': 'sORFTBvqnhWCekwPSNpw', 'utm_adcontent': 'unknown', 'utm_keyword': 'GdRWiswMRFnUQdWCHqxX', 'device_category': 'mobile', 'device_os': 'iOS', 'device_brand': 'Apple', 'device_screen_resolution': '390x844', 'device_browser': 'Safari', 'geo_country': 'Russia', 'geo_city': 'Moscow'}, {'session_id': '9060515112083893459.1641131273.1641131273', 'client_id': '2109565565.1641131219', 'visit_date': datetime.datetime(2022, 1, 2, 0, 0), 'visit_time': datetime.time(16, 47, 53), 'visit_number': 2, 'utm_source': 'EbeDysvbnjmdQavikNXY', 'utm_medium': 'referral', 'utm_campaign': 'XOywtQLVBIVeKsBULENc', 'utm_adcontent': 'vmpjxytvOioeqSlwNoAl', 'utm_keyword': 'BhUZBJUdmsWLEISSdxTa', 'device_category': 'mobile', 'device_os': 'iOS', 'device_brand': 'Apple', 'device_screen_resolution': '390x844', 'device_browser': 'Safari', 'geo_country': 'Russia', 'geo_city': 'Moscow'}, {'session_id': '9060834009110052863.1641136989.1641136989', 'client_id': '2109639814.1640529919', 'visit_date': datetime.datetime(2022, 1, 2, 0, 0), 'visit_time': datetime.time(18, 23, 9), 'visit_number': 2, 'utm_source': 'sORFTBvqnhWCekwPSNpw', 'utm_medium': 'banner', 'utm_campaign': 'EtfLrwPWorOxUtcoUEYQ', 'utm_adcontent': 'XuLWchPRHivTUPkStLhY', 'utm_keyword': 'BhUZBJUdmsWLEISSdxTa', 'device_category': 'mobile', 'device_os': 'Android', 'device_brand': '(not set)', 'device_screen_resolution': '393x873', 'device_browser': 'Chrome', 'geo_country': 'Russia', 'geo_city': 'Novosibirsk'}, {'session_id': '9062217731609300312.1641123162.1641123162', 'client_id': '2109961987.1641123160', 'visit_date': datetime.datetime(2022, 1, 2, 0, 0), 'visit_time': datetime.time(14, 32, 42), 'visit_number': 1, 'utm_source': 'sORFTBvqnhWCekwPSNpw', 'utm_medium': 'banner', 'utm_campaign': 'EtfLrwPWorOxUtcoUEYQ', 'utm_adcontent': 'XuLWchPRHivTUPkStLhY', 'utm_keyword': 'BhUZBJUdmsWLEISSdxTa', 'device_category': 'mobile', 'device_os': 'Android', 'device_brand': 'Huawei', 'device_screen_resolution': '427x939', 'device_browser': 'Chrome', 'geo_country': 'Russia', 'geo_city': 'Krasnodar'}  ... displaying 10 of 7277 total bound parameter sets ...  {'session_id': '9054597699416948180.1641086571.1641086571', 'client_id': '2108187810.1641086420', 'visit_date': datetime.datetime(2022, 1, 2, 0, 0), 'visit_time': datetime.time(4, 22, 51), 'visit_number': 2, 'utm_source': 'sORFTBvqnhWCekwPSNpw', 'utm_medium': 'banner', 'utm_campaign': 'UbsMmmrDEFnwCqrzceMX', 'utm_adcontent': 'vmpjxytvOioeqSlwNoAl', 'utm_keyword': 'BhUZBJUdmsWLEISSdxTa', 'device_category': 'mobile', 'device_os': 'Android', 'device_brand': 'Xiaomi', 'device_screen_resolution': '393x699', 'device_browser': 'Chrome', 'geo_country': 'Russia', 'geo_city': 'Moscow'}, {'session_id': '9054597699416948180.1641140115.1641140115', 'client_id': '2108187810.1641086420', 'visit_date': datetime.datetime(2022, 1, 2, 0, 0), 'visit_time': datetime.time(19, 15, 15), 'visit_number': 3, 'utm_source': 'sORFTBvqnhWCekwPSNpw', 'utm_medium': 'banner', 'utm_campaign': 'UbsMmmrDEFnwCqrzceMX', 'utm_adcontent': 'vmpjxytvOioeqSlwNoAl', 'utm_keyword': 'BhUZBJUdmsWLEISSdxTa', 'device_category': 'mobile', 'device_os': 'Android', 'device_brand': 'Xiaomi', 'device_screen_resolution': '393x699', 'device_browser': 'Chrome', 'geo_country': 'Russia', 'geo_city': 'Moscow'})]
(Background on this error at: https://sqlalche.me/e/14/gkpj)
2025-05-09 20:29:20 - ERROR - Failed to send log to Elasticsearch: Connection error caused by: ConnectionError(Connection error caused by: NameResolutionError(<urllib3.connection.HTTPConnection object at 0x000001FA527447C0>: Failed to resolve 'elasticsearch' ([Errno 11001] getaddrinfo failed)))
2025-05-09 20:29:20 - ERROR - Failed to send log to Elasticsearch: RetryError[<Future at 0x1fa50fdef20 state=finished raised ConnectionError>]
2025-05-09 20:29:52 - ERROR - Missing columns: ['client_id', 'visit_date', 'visit_time', 'visit_number', 'utm_source', 'utm_medium', 'utm_campaign', 'utm_adcontent', 'utm_keyword', 'device_category', 'device_os', 'device_brand', 'device_screen_resolution', 'device_browser', 'geo_country', 'geo_city'].
2025-05-09 20:30:08 - ERROR - Failed to send log to Elasticsearch: Connection error caused by: ConnectionError(Connection error caused by: NameResolutionError(<urllib3.connection.HTTPConnection object at 0x0000018EE3A54490>: Failed to resolve 'elasticsearch' ([Errno 11001] getaddrinfo failed)))
2025-05-09 20:30:08 - ERROR - Failed to send log to Elasticsearch: RetryError[<Future at 0x18ed6a1fbb0 state=finished raised ConnectionError>]
2025-05-09 20:30:08 - WARNING - File ga_sessions_new_2022-01-01.json contains no valid sessions. Skipping.
2025-05-09 20:30:25 - ERROR - Failed to send log to Elasticsearch: Connection error caused by: ConnectionError(Connection error caused by: NameResolutionError(<urllib3.connection.HTTPConnection object at 0x0000018EE3A551B0>: Failed to resolve 'elasticsearch' ([Errno 11001] getaddrinfo failed)))
2025-05-09 20:30:25 - ERROR - Failed to send log to Elasticsearch: RetryError[<Future at 0x18ed6a1faf0 state=finished raised ConnectionError>]
2025-05-09 20:30:25 - WARNING - File ga_sessions_new_2022-01-02.json has already been loaded. Skipping.
2025-05-09 20:30:41 - ERROR - Failed to send log to Elasticsearch: Connection error caused by: ConnectionError(Connection error caused by: NameResolutionError(<urllib3.connection.HTTPConnection object at 0x0000018EE3A563B0>: Failed to resolve 'elasticsearch' ([Errno 11001] getaddrinfo failed)))
2025-05-09 20:30:41 - ERROR - Failed to send log to Elasticsearch: RetryError[<Future at 0x18ee3a560e0 state=finished raised ConnectionError>]
2025-05-09 20:30:41 - INFO - All files have been processed.
2025-05-09 20:30:41 - INFO - Sending ga_sessions_new_2022-01-02.pkl to DB...
2025-05-09 20:30:41 - ERROR - DB load error for ga_sessions_new_2022-01-02.pkl: (psycopg2.errors.UniqueViolation) duplicate key value violates unique constraint "sessions_pkey"
DETAIL:  Key (session_id)=(9055432108483400094.1641140638.1641140638) already exists.

[SQL: INSERT INTO sessions (session_id, client_id, visit_date, visit_time, visit_number, utm_source, utm_medium, utm_campaign, utm_adcontent, utm_keyword, device_category, device_os, device_brand, device_screen_resolution, device_browser, geo_country, geo_city) VALUES (%(session_id)s, %(client_id)s, %(visit_date)s, %(visit_time)s, %(visit_number)s, %(utm_source)s, %(utm_medium)s, %(utm_campaign)s, %(utm_adcontent)s, %(utm_keyword)s, %(device_category)s, %(device_os)s, %(device_brand)s, %(device_screen_resolution)s, %(device_browser)s, %(geo_country)s, %(geo_city)s)]
[parameters: ({'session_id': '9055432108483400094.1641140638.1641140638', 'client_id': '2108382086.1641140638', 'visit_date': datetime.datetime(2022, 1, 2, 0, 0), 'visit_time': datetime.time(19, 23, 58), 'visit_number': 1, 'utm_source': 'hqpYkWpkYefgduliaKcm', 'utm_medium': 'cpc', 'utm_campaign': 'unknown', 'utm_adcontent': 'vmpjxytvOioeqSlwNoAl', 'utm_keyword': 'BhUZBJUdmsWLEISSdxTa', 'device_category': 'mobile', 'device_os': 'Android', 'device_brand': 'Xiaomi', 'device_screen_resolution': '393x851', 'device_browser': 'Android Webview', 'geo_country': 'Russia', 'geo_city': 'Moscow'}, {'session_id': '9056424722670117391.1641112635.1641112635', 'client_id': '2108613197.1641112079', 'visit_date': datetime.datetime(2022, 1, 2, 0, 0), 'visit_time': datetime.time(11, 37, 15), 'visit_number': 1, 'utm_source': 'kVGXyneGKJVfHKWnWbEr', 'utm_medium': '(none)', 'utm_campaign': 'XOywtQLVBIVeKsBULENc', 'utm_adcontent': 'vmpjxytvOioeqSlwNoAl', 'utm_keyword': 'BhUZBJUdmsWLEISSdxTa', 'device_category': 'mobile', 'device_os': 'Android', 'device_brand': 'Lenovo', 'device_screen_resolution': '412x915', 'device_browser': 'Chrome', 'geo_country': 'Russia', 'geo_city': 'Kazan'}, {'session_id': '9058564964994900640.1641153986.1641153986', 'client_id': '2109111511.1632756384', 'visit_date': datetime.datetime(2022, 1, 2, 0, 0), 'visit_time': datetime.time(23, 6, 26), 'visit_number': 2, 'utm_source': 'hqpYkWpkYefgduliaKcm', 'utm_medium': 'cpc', 'utm_campaign': 'unknown', 'utm_adcontent': 'vmpjxytvOioeqSlwNoAl', 'utm_keyword': 'BhUZBJUdmsWLEISSdxTa', 'device_category': 'mobile', 'device_os': 'Android', 'device_brand': 'Samsung', 'device_screen_resolution': '360x740', 'device_browser': 'Android Webview', 'geo_country': 'Russia', 'geo_city': 'Saint Petersburg'}, {'session_id': '9059738831104859637.1641111028.1641111028', 'client_id': '2109384823.1641111029', 'visit_date': datetime.datetime(2022, 1, 2, 0, 0), 'visit_time': datetime.time(11, 10, 28), 'visit_number': 1, 'utm_source': 'sORFTBvqnhWCekwPSNpw', 'utm_medium': 'banner', 'utm_campaign': 'EtfLrwPWorOxUtcoUEYQ', 'utm_adcontent': 'XuLWchPRHivTUPkStLhY', 'utm_keyword': 'BhUZBJUdmsWLEISSdxTa', 'device_category': 'mobile', 'device_os': 'iOS', 'device_brand': 'Apple', 'device_screen_resolution': '414x896', 'device_browser': 'Safari', 'geo_country': 'Russia', 'geo_city': 'Moscow'}, {'session_id': '9060515112083893459.1641131219.1641131219', 'client_id': '2109565565.1641131219', 'visit_date': datetime.datetime(2022, 1, 2, 0, 0), 'visit_time': datetime.time(16, 46, 59), 'visit_number': 1, 'utm_source': 'CVoLfHiSYnQlpfwfKDvK', 'utm_medium': 'cpc', 'utm_campaign': 'sORFTBvqnhWCekwPSNpw', 'utm_adcontent': 'unknown', 'utm_keyword': 'GdRWiswMRFnUQdWCHqxX', 'device_category': 'mobile', 'device_os': 'iOS', 'device_brand': 'Apple', 'device_screen_resolution': '390x844', 'device_browser': 'Safari', 'geo_country': 'Russia', 'geo_city': 'Moscow'}, {'session_id': '9060515112083893459.1641131273.1641131273', 'client_id': '2109565565.1641131219', 'visit_date': datetime.datetime(2022, 1, 2, 0, 0), 'visit_time': datetime.time(16, 47, 53), 'visit_number': 2, 'utm_source': 'EbeDysvbnjmdQavikNXY', 'utm_medium': 'referral', 'utm_campaign': 'XOywtQLVBIVeKsBULENc', 'utm_adcontent': 'vmpjxytvOioeqSlwNoAl', 'utm_keyword': 'BhUZBJUdmsWLEISSdxTa', 'device_category': 'mobile', 'device_os': 'iOS', 'device_brand': 'Apple', 'device_screen_resolution': '390x844', 'device_browser': 'Safari', 'geo_country': 'Russia', 'geo_city': 'Moscow'}, {'session_id': '9060834009110052863.1641136989.1641136989', 'client_id': '2109639814.1640529919', 'visit_date': datetime.datetime(2022, 1, 2, 0, 0), 'visit_time': datetime.time(18, 23, 9), 'visit_number': 2, 'utm_source': 'sORFTBvqnhWCekwPSNpw', 'utm_medium': 'banner', 'utm_campaign': 'EtfLrwPWorOxUtcoUEYQ', 'utm_adcontent': 'XuLWchPRHivTUPkStLhY', 'utm_keyword': 'BhUZBJUdmsWLEISSdxTa', 'device_category': 'mobile', 'device_os': 'Android', 'device_brand': '(not set)', 'device_screen_resolution': '393x873', 'device_browser': 'Chrome', 'geo_country': 'Russia', 'geo_city': 'Novosibirsk'}, {'session_id': '9062217731609300312.1641123162.1641123162', 'client_id': '2109961987.1641123160', 'visit_date': datetime.datetime(2022, 1, 2, 0, 0), 'visit_time': datetime.time(14, 32, 42), 'visit_number': 1, 'utm_source': 'sORFTBvqnhWCekwPSNpw', 'utm_medium': 'banner', 'utm_campaign': 'EtfLrwPWorOxUtcoUEYQ', 'utm_adcontent': 'XuLWchPRHivTUPkStLhY', 'utm_keyword': 'BhUZBJUdmsWLEISSdxTa', 'device_category': 'mobile', 'device_os': 'Android', 'device_brand': 'Huawei', 'device_screen_resolution': '427x939', 'device_browser': 'Chrome', 'geo_country': 'Russia', 'geo_city': 'Krasnodar'}  ... displaying 10 of 7277 total bound parameter sets ...  {'session_id': '9054597699416948180.1641086571.1641086571', 'client_id': '2108187810.1641086420', 'visit_date': datetime.datetime(2022, 1, 2, 0, 0), 'visit_time': datetime.time(4, 22, 51), 'visit_number': 2, 'utm_source': 'sORFTBvqnhWCekwPSNpw', 'utm_medium': 'banner', 'utm_campaign': 'UbsMmmrDEFnwCqrzceMX', 'utm_adcontent': 'vmpjxytvOioeqSlwNoAl', 'utm_keyword': 'BhUZBJUdmsWLEISSdxTa', 'device_category': 'mobile', 'device_os': 'Android', 'device_brand': 'Xiaomi', 'device_screen_resolution': '393x699', 'device_browser': 'Chrome', 'geo_country': 'Russia', 'geo_city': 'Moscow'}, {'session_id': '9054597699416948180.1641140115.1641140115', 'client_id': '2108187810.1641086420', 'visit_date': datetime.datetime(2022, 1, 2, 0, 0), 'visit_time': datetime.time(19, 15, 15), 'visit_number': 3, 'utm_source': 'sORFTBvqnhWCekwPSNpw', 'utm_medium': 'banner', 'utm_campaign': 'UbsMmmrDEFnwCqrzceMX', 'utm_adcontent': 'vmpjxytvOioeqSlwNoAl', 'utm_keyword': 'BhUZBJUdmsWLEISSdxTa', 'device_category': 'mobile', 'device_os': 'Android', 'device_brand': 'Xiaomi', 'device_screen_resolution': '393x699', 'device_browser': 'Chrome', 'geo_country': 'Russia', 'geo_city': 'Moscow'})]
(Background on this error at: https://sqlalche.me/e/14/gkpj)
2025-05-09 20:30:58 - ERROR - Failed to send log to Elasticsearch: Connection error caused by: ConnectionError(Connection error caused by: NameResolutionError(<urllib3.connection.HTTPConnection object at 0x0000018EE21A8520>: Failed to resolve 'elasticsearch' ([Errno 11001] getaddrinfo failed)))
2025-05-09 20:30:58 - ERROR - Failed to send log to Elasticsearch: RetryError[<Future at 0x18ed6bf6c80 state=finished raised ConnectionError>]
2025-05-09 20:31:43 - WARNING - File ga_sessions_new_2022-01-01.json contains no valid sessions. Skipping.
2025-05-09 20:32:00 - ERROR - Failed to send log to Elasticsearch: Connection error caused by: ConnectionError(Connection error caused by: NameResolutionError(<urllib3.connection.HTTPConnection object at 0x000001DF7E190040>: Failed to resolve 'elasticsearch' ([Errno 11001] getaddrinfo failed)))
2025-05-09 20:32:00 - ERROR - Failed to send log to Elasticsearch: RetryError[<Future at 0x1df7e15fcd0 state=finished raised ConnectionError>]
2025-05-09 20:32:00 - WARNING - File ga_sessions_new_2022-01-02.json has already been loaded. Skipping.
2025-05-09 20:32:16 - ERROR - Failed to send log to Elasticsearch: Connection error caused by: ConnectionError(Connection error caused by: NameResolutionError(<urllib3.connection.HTTPConnection object at 0x000001DF7E191210>: Failed to resolve 'elasticsearch' ([Errno 11001] getaddrinfo failed)))
2025-05-09 20:32:16 - ERROR - Failed to send log to Elasticsearch: RetryError[<Future at 0x1df7e190f40 state=finished raised ConnectionError>]
2025-05-09 20:32:16 - INFO - Transformed data saved to C:\Users\Ekaterina\sber_de\de_for_sber\data\processed\new_sessions\ga_sessions_new_2022-01-03.pkl
2025-05-09 20:32:16 - INFO - All files have been processed.
2025-05-09 20:32:16 - INFO - Sending ga_sessions_new_2022-01-02.pkl to DB...
2025-05-09 20:32:17 - ERROR - DB load error for ga_sessions_new_2022-01-02.pkl: (psycopg2.errors.UniqueViolation) duplicate key value violates unique constraint "sessions_pkey"
DETAIL:  Key (session_id)=(9055432108483400094.1641140638.1641140638) already exists.

[SQL: INSERT INTO sessions (session_id, client_id, visit_date, visit_time, visit_number, utm_source, utm_medium, utm_campaign, utm_adcontent, utm_keyword, device_category, device_os, device_brand, device_screen_resolution, device_browser, geo_country, geo_city) VALUES (%(session_id)s, %(client_id)s, %(visit_date)s, %(visit_time)s, %(visit_number)s, %(utm_source)s, %(utm_medium)s, %(utm_campaign)s, %(utm_adcontent)s, %(utm_keyword)s, %(device_category)s, %(device_os)s, %(device_brand)s, %(device_screen_resolution)s, %(device_browser)s, %(geo_country)s, %(geo_city)s)]
[parameters: ({'session_id': '9055432108483400094.1641140638.1641140638', 'client_id': '2108382086.1641140638', 'visit_date': datetime.datetime(2022, 1, 2, 0, 0), 'visit_time': datetime.time(19, 23, 58), 'visit_number': 1, 'utm_source': 'hqpYkWpkYefgduliaKcm', 'utm_medium': 'cpc', 'utm_campaign': 'unknown', 'utm_adcontent': 'vmpjxytvOioeqSlwNoAl', 'utm_keyword': 'BhUZBJUdmsWLEISSdxTa', 'device_category': 'mobile', 'device_os': 'Android', 'device_brand': 'Xiaomi', 'device_screen_resolution': '393x851', 'device_browser': 'Android Webview', 'geo_country': 'Russia', 'geo_city': 'Moscow'}, {'session_id': '9056424722670117391.1641112635.1641112635', 'client_id': '2108613197.1641112079', 'visit_date': datetime.datetime(2022, 1, 2, 0, 0), 'visit_time': datetime.time(11, 37, 15), 'visit_number': 1, 'utm_source': 'kVGXyneGKJVfHKWnWbEr', 'utm_medium': '(none)', 'utm_campaign': 'XOywtQLVBIVeKsBULENc', 'utm_adcontent': 'vmpjxytvOioeqSlwNoAl', 'utm_keyword': 'BhUZBJUdmsWLEISSdxTa', 'device_category': 'mobile', 'device_os': 'Android', 'device_brand': 'Lenovo', 'device_screen_resolution': '412x915', 'device_browser': 'Chrome', 'geo_country': 'Russia', 'geo_city': 'Kazan'}, {'session_id': '9058564964994900640.1641153986.1641153986', 'client_id': '2109111511.1632756384', 'visit_date': datetime.datetime(2022, 1, 2, 0, 0), 'visit_time': datetime.time(23, 6, 26), 'visit_number': 2, 'utm_source': 'hqpYkWpkYefgduliaKcm', 'utm_medium': 'cpc', 'utm_campaign': 'unknown', 'utm_adcontent': 'vmpjxytvOioeqSlwNoAl', 'utm_keyword': 'BhUZBJUdmsWLEISSdxTa', 'device_category': 'mobile', 'device_os': 'Android', 'device_brand': 'Samsung', 'device_screen_resolution': '360x740', 'device_browser': 'Android Webview', 'geo_country': 'Russia', 'geo_city': 'Saint Petersburg'}, {'session_id': '9059738831104859637.1641111028.1641111028', 'client_id': '2109384823.1641111029', 'visit_date': datetime.datetime(2022, 1, 2, 0, 0), 'visit_time': datetime.time(11, 10, 28), 'visit_number': 1, 'utm_source': 'sORFTBvqnhWCekwPSNpw', 'utm_medium': 'banner', 'utm_campaign': 'EtfLrwPWorOxUtcoUEYQ', 'utm_adcontent': 'XuLWchPRHivTUPkStLhY', 'utm_keyword': 'BhUZBJUdmsWLEISSdxTa', 'device_category': 'mobile', 'device_os': 'iOS', 'device_brand': 'Apple', 'device_screen_resolution': '414x896', 'device_browser': 'Safari', 'geo_country': 'Russia', 'geo_city': 'Moscow'}, {'session_id': '9060515112083893459.1641131219.1641131219', 'client_id': '2109565565.1641131219', 'visit_date': datetime.datetime(2022, 1, 2, 0, 0), 'visit_time': datetime.time(16, 46, 59), 'visit_number': 1, 'utm_source': 'CVoLfHiSYnQlpfwfKDvK', 'utm_medium': 'cpc', 'utm_campaign': 'sORFTBvqnhWCekwPSNpw', 'utm_adcontent': 'unknown', 'utm_keyword': 'GdRWiswMRFnUQdWCHqxX', 'device_category': 'mobile', 'device_os': 'iOS', 'device_brand': 'Apple', 'device_screen_resolution': '390x844', 'device_browser': 'Safari', 'geo_country': 'Russia', 'geo_city': 'Moscow'}, {'session_id': '9060515112083893459.1641131273.1641131273', 'client_id': '2109565565.1641131219', 'visit_date': datetime.datetime(2022, 1, 2, 0, 0), 'visit_time': datetime.time(16, 47, 53), 'visit_number': 2, 'utm_source': 'EbeDysvbnjmdQavikNXY', 'utm_medium': 'referral', 'utm_campaign': 'XOywtQLVBIVeKsBULENc', 'utm_adcontent': 'vmpjxytvOioeqSlwNoAl', 'utm_keyword': 'BhUZBJUdmsWLEISSdxTa', 'device_category': 'mobile', 'device_os': 'iOS', 'device_brand': 'Apple', 'device_screen_resolution': '390x844', 'device_browser': 'Safari', 'geo_country': 'Russia', 'geo_city': 'Moscow'}, {'session_id': '9060834009110052863.1641136989.1641136989', 'client_id': '2109639814.1640529919', 'visit_date': datetime.datetime(2022, 1, 2, 0, 0), 'visit_time': datetime.time(18, 23, 9), 'visit_number': 2, 'utm_source': 'sORFTBvqnhWCekwPSNpw', 'utm_medium': 'banner', 'utm_campaign': 'EtfLrwPWorOxUtcoUEYQ', 'utm_adcontent': 'XuLWchPRHivTUPkStLhY', 'utm_keyword': 'BhUZBJUdmsWLEISSdxTa', 'device_category': 'mobile', 'device_os': 'Android', 'device_brand': '(not set)', 'device_screen_resolution': '393x873', 'device_browser': 'Chrome', 'geo_country': 'Russia', 'geo_city': 'Novosibirsk'}, {'session_id': '9062217731609300312.1641123162.1641123162', 'client_id': '2109961987.1641123160', 'visit_date': datetime.datetime(2022, 1, 2, 0, 0), 'visit_time': datetime.time(14, 32, 42), 'visit_number': 1, 'utm_source': 'sORFTBvqnhWCekwPSNpw', 'utm_medium': 'banner', 'utm_campaign': 'EtfLrwPWorOxUtcoUEYQ', 'utm_adcontent': 'XuLWchPRHivTUPkStLhY', 'utm_keyword': 'BhUZBJUdmsWLEISSdxTa', 'device_category': 'mobile', 'device_os': 'Android', 'device_brand': 'Huawei', 'device_screen_resolution': '427x939', 'device_browser': 'Chrome', 'geo_country': 'Russia', 'geo_city': 'Krasnodar'}  ... displaying 10 of 7277 total bound parameter sets ...  {'session_id': '9054597699416948180.1641086571.1641086571', 'client_id': '2108187810.1641086420', 'visit_date': datetime.datetime(2022, 1, 2, 0, 0), 'visit_time': datetime.time(4, 22, 51), 'visit_number': 2, 'utm_source': 'sORFTBvqnhWCekwPSNpw', 'utm_medium': 'banner', 'utm_campaign': 'UbsMmmrDEFnwCqrzceMX', 'utm_adcontent': 'vmpjxytvOioeqSlwNoAl', 'utm_keyword': 'BhUZBJUdmsWLEISSdxTa', 'device_category': 'mobile', 'device_os': 'Android', 'device_brand': 'Xiaomi', 'device_screen_resolution': '393x699', 'device_browser': 'Chrome', 'geo_country': 'Russia', 'geo_city': 'Moscow'}, {'session_id': '9054597699416948180.1641140115.1641140115', 'client_id': '2108187810.1641086420', 'visit_date': datetime.datetime(2022, 1, 2, 0, 0), 'visit_time': datetime.time(19, 15, 15), 'visit_number': 3, 'utm_source': 'sORFTBvqnhWCekwPSNpw', 'utm_medium': 'banner', 'utm_campaign': 'UbsMmmrDEFnwCqrzceMX', 'utm_adcontent': 'vmpjxytvOioeqSlwNoAl', 'utm_keyword': 'BhUZBJUdmsWLEISSdxTa', 'device_category': 'mobile', 'device_os': 'Android', 'device_brand': 'Xiaomi', 'device_screen_resolution': '393x699', 'device_browser': 'Chrome', 'geo_country': 'Russia', 'geo_city': 'Moscow'})]
(Background on this error at: https://sqlalche.me/e/14/gkpj)
2025-05-09 20:32:33 - ERROR - Failed to send log to Elasticsearch: Connection error caused by: ConnectionError(Connection error caused by: NameResolutionError(<urllib3.connection.HTTPConnection object at 0x000001DF7EC06800>: Failed to resolve 'elasticsearch' ([Errno 11001] getaddrinfo failed)))
2025-05-09 20:32:33 - ERROR - Failed to send log to Elasticsearch: RetryError[<Future at 0x1df7ec06d10 state=finished raised ConnectionError>]
2025-05-09 20:40:23 - WARNING - File ga_sessions_new_2022-01-01.json contains no valid sessions. Skipping.
2025-05-09 20:40:39 - ERROR - Failed to send log to Elasticsearch: Connection error caused by: ConnectionError(Connection error caused by: NameResolutionError(<urllib3.connection.HTTPConnection object at 0x0000018BE90F3040>: Failed to resolve 'elasticsearch' ([Errno 11001] getaddrinfo failed)))
2025-05-09 20:40:39 - ERROR - Failed to send log to Elasticsearch: RetryError[<Future at 0x18be90f3370 state=finished raised ConnectionError>]
2025-05-09 20:40:39 - WARNING - File ga_sessions_new_2022-01-02.json has already been loaded. Skipping.
2025-05-09 20:40:55 - ERROR - Failed to send log to Elasticsearch: Connection error caused by: ConnectionError(Connection error caused by: NameResolutionError(<urllib3.connection.HTTPConnection object at 0x0000018BE90F2140>: Failed to resolve 'elasticsearch' ([Errno 11001] getaddrinfo failed)))
2025-05-09 20:40:55 - ERROR - Failed to send log to Elasticsearch: RetryError[<Future at 0x18be90f2410 state=finished raised ConnectionError>]
2025-05-09 20:40:55 - WARNING - File ga_sessions_new_2022-01-03.json has already been loaded. Skipping.
2025-05-09 20:41:11 - ERROR - Failed to send log to Elasticsearch: Connection error caused by: ConnectionError(Connection error caused by: NameResolutionError(<urllib3.connection.HTTPConnection object at 0x0000018BE90F0F40>: Failed to resolve 'elasticsearch' ([Errno 11001] getaddrinfo failed)))
2025-05-09 20:41:11 - ERROR - Failed to send log to Elasticsearch: RetryError[<Future at 0x18be90f1210 state=finished raised ConnectionError>]
2025-05-09 20:41:11 - INFO - All files have been processed.
2025-05-09 20:41:11 - INFO - Sending ga_sessions_new_2022-01-02.pkl to DB...
2025-05-09 20:41:18 - WARNING - Skipped ga_sessions_new_2022-01-02.pkl (duplicates found in DB). Marking as processed.
2025-05-09 20:41:34 - ERROR - Failed to send log to Elasticsearch: Connection error caused by: ConnectionError(Connection error caused by: NameResolutionError(<urllib3.connection.HTTPConnection object at 0x0000018BEAB27D30>: Failed to resolve 'elasticsearch' ([Errno 11001] getaddrinfo failed)))
2025-05-09 20:41:34 - ERROR - Failed to send log to Elasticsearch: RetryError[<Future at 0x18beab27fa0 state=finished raised ConnectionError>]
2025-05-09 20:41:34 - INFO - Sending ga_sessions_new_2022-01-03.pkl to DB...
2025-05-09 20:41:43 - INFO - Success: ga_sessions_new_2022-01-03.pkl loaded to DB
2025-05-09 20:41:43 - WARNING - File ga_sessions_new_2022-01-01.json contains no valid sessions. Skipping.
2025-05-09 20:42:00 - ERROR - Failed to send log to Elasticsearch: Connection error caused by: ConnectionError(Connection error caused by: NameResolutionError(<urllib3.connection.HTTPConnection object at 0x0000018BE936D870>: Failed to resolve 'elasticsearch' ([Errno 11001] getaddrinfo failed)))
2025-05-09 20:42:00 - ERROR - Failed to send log to Elasticsearch: RetryError[<Future at 0x18be936db10 state=finished raised ConnectionError>]
2025-05-09 20:42:00 - WARNING - File ga_sessions_new_2022-01-02.json has already been loaded. Skipping.
2025-05-09 20:42:16 - ERROR - Failed to send log to Elasticsearch: Connection error caused by: ConnectionError(Connection error caused by: NameResolutionError(<urllib3.connection.HTTPConnection object at 0x0000018BE936DC60>: Failed to resolve 'elasticsearch' ([Errno 11001] getaddrinfo failed)))
2025-05-09 20:42:16 - ERROR - Failed to send log to Elasticsearch: RetryError[<Future at 0x18be936cd90 state=finished raised ConnectionError>]
2025-05-09 20:42:16 - WARNING - File ga_sessions_new_2022-01-03.json has already been loaded. Skipping.
2025-05-09 20:42:32 - ERROR - Failed to send log to Elasticsearch: Connection error caused by: ConnectionError(Connection error caused by: NameResolutionError(<urllib3.connection.HTTPConnection object at 0x0000018BE936D360>: Failed to resolve 'elasticsearch' ([Errno 11001] getaddrinfo failed)))
2025-05-09 20:42:32 - ERROR - Failed to send log to Elasticsearch: RetryError[<Future at 0x18be936d180 state=finished raised ConnectionError>]
2025-05-09 20:42:32 - INFO - All files have been processed.
2025-05-09 21:00:43 - WARNING - File ga_sessions_new_2022-01-01.json contains no valid sessions. Skipping.
2025-05-09 21:00:59 - ERROR - Failed to send log to Elasticsearch: Connection error caused by: ConnectionError(Connection error caused by: NameResolutionError(<urllib3.connection.HTTPConnection object at 0x000001C78072A500>: Failed to resolve 'elasticsearch' ([Errno 11001] getaddrinfo failed)))
2025-05-09 21:00:59 - ERROR - Failed to send log to Elasticsearch: RetryError[<Future at 0x1c78072a1d0 state=finished raised ConnectionError>]
2025-05-09 21:00:59 - WARNING - File ga_sessions_new_2022-01-02.json has already been loaded. Skipping.
2025-05-09 21:01:15 - ERROR - Failed to send log to Elasticsearch: Connection error caused by: ConnectionError(Connection error caused by: NameResolutionError(<urllib3.connection.HTTPConnection object at 0x000001C78072B490>: Failed to resolve 'elasticsearch' ([Errno 11001] getaddrinfo failed)))
2025-05-09 21:01:15 - ERROR - Failed to send log to Elasticsearch: RetryError[<Future at 0x1c78072b1c0 state=finished raised ConnectionError>]
2025-05-09 21:01:15 - WARNING - File ga_sessions_new_2022-01-03.json has already been loaded. Skipping.
2025-05-09 21:01:36 - ERROR - Failed to load flags: Error 11001 connecting to redis_flags:6379. getaddrinfo failed.
2025-05-09 21:01:52 - ERROR - Failed to send log to Elasticsearch: Connection error caused by: ConnectionError(Connection error caused by: NameResolutionError(<urllib3.connection.HTTPConnection object at 0x000001F5AC874A90>: Failed to resolve 'elasticsearch' ([Errno 11001] getaddrinfo failed)))
2025-05-09 21:01:52 - ERROR - Failed to send to ES: RetryError[<Future at 0x1f5ac874760 state=finished raised ConnectionError>]
